[0m[33m2020-06-01 18:34:16,877 [1m[33mlibqtile pacman.py:__init__():L38 [0m Pacman is deprecated, please use CheckUpdates[0m
[0m[33m2020-06-01 18:34:17,050 [1m[33mlibqtile pacman.py:__init__():L38 [0m Pacman is deprecated, please use CheckUpdates[0m
[0m[33m2020-06-01 18:34:17,052 [1m[33mlibqtile pacman.py:__init__():L38 [0m Pacman is deprecated, please use CheckUpdates[0m
[ 01/06/20 18:34:17.421 parse_config_libconfig WARN ] Option `no-dock-shadow` is deprecated, and will be removed. Please use the wintype option `shadow` of `dock` instead.
[ 01/06/20 18:34:17.421 parse_config_libconfig WARN ] Option `no-dnd-shadow` is deprecated, and will be removed. Please use the wintype option `shadow` of `dnd` instead.
[ 01/06/20 18:34:17.421 parse_config_libconfig WARN ] Option `menu-opacity` is deprecated, and will be removed.Please use the wintype option `opacity` of `popup_menu` and `dropdown_menu` instead.
[ 01/06/20 18:34:17.421 parse_config_libconfig WARN ] vsync option will take a boolean from now on. "opengl-swc" is interpreted as "true" for compatibility, but this will stop working soon
[ 01/06/20 18:34:17.421 parse_config_libconfig WARN ] glx-swap-method has been deprecated since v6, your setting "exchange" should be replaced by `use-damage = true`.
[ 01/06/20 18:34:17.421 parse_config_libconfig WARN ] "clear-shadow" is removed as an option, and is always enabled now. Consider removing it from your config file
[ 01/06/20 18:34:17.421 session_init WARN ] This compositor has been renamed to "picom", the "compton" binary will not be installed in the future.
[ 01/06/20 18:34:17.517 swopti_init WARN ] --sw-opti is going to be deprecated. If you get real benefits from using this option, please open an issue to let us know.

(nitrogen:329779): Gtk-WARNING **: 18:34:17.525: Unable to locate theme engine in module_path: "murrine",

(nitrogen:329779): Gtk-WARNING **: 18:34:17.525: Unable to locate theme engine in module_path: "murrine",

(nitrogen:329779): Gtk-WARNING **: 18:34:17.525: Unable to locate theme engine in module_path: "murrine",

(nitrogen:329779): Gtk-WARNING **: 18:34:17.528: Unable to locate theme engine in module_path: "murrine",

(nitrogen:329779): Gtk-WARNING **: 18:34:17.528: Unable to locate theme engine in module_path: "murrine",

(nitrogen:329779): Gtk-WARNING **: 18:34:17.528: Unable to locate theme engine in module_path: "murrine",

(nitrogen:329779): Gtk-WARNING **: 18:34:17.530: Unable to locate theme engine in module_path: "murrine",

(nitrogen:329779): Gtk-WARNING **: 18:34:17.530: Unable to locate theme engine in module_path: "murrine",

(nitrogen:329779): Gtk-WARNING **: 18:34:17.530: Unable to locate theme engine in module_path: "murrine",

(nitrogen:329779): Gtk-WARNING **: 18:34:17.530: Unable to locate theme engine in module_path: "murrine",

(nitrogen:329779): Gtk-WARNING **: 18:34:17.531: Unable to locate theme engine in module_path: "murrine",

(nm-applet:329781): Gtk-WARNING **: 18:34:17.895: Theme directory 32@2x/devices of theme Vimix-Doder-dark has no size field


(nitrogen:329779): Gtk-WARNING **: 18:34:17.949: Unable to locate theme engine in module_path: "murrine",

(nitrogen:329779): Gtk-WARNING **: 18:34:17.949: Unable to locate theme engine in module_path: "murrine",

(nitrogen:329779): Gtk-WARNING **: 18:34:17.949: Unable to locate theme engine in module_path: "murrine",

(nitrogen:329779): Gtk-WARNING **: 18:34:17.952: Unable to locate theme engine in module_path: "murrine",

(nitrogen:329779): Gtk-WARNING **: 18:34:17.952: Unable to locate theme engine in module_path: "murrine",

(nitrogen:329779): Gtk-WARNING **: 18:34:17.952: Unable to locate theme engine in module_path: "murrine",

(nitrogen:329779): Gtk-WARNING **: 18:34:17.953: Unable to locate theme engine in module_path: "murrine",

(nitrogen:329779): Gtk-WARNING **: 18:34:17.954: Unable to locate theme engine in module_path: "murrine",

(nitrogen:329779): Gtk-WARNING **: 18:34:17.954: Unable to locate theme engine in module_path: "murrine",

(nitrogen:329779): Gtk-WARNING **: 18:34:17.954: Unable to locate theme engine in module_path: "murrine",

(nitrogen:329779): Gtk-WARNING **: 18:34:17.954: Unable to locate theme engine in module_path: "murrine",

(blueman-applet:329782): Gtk-WARNING **: 18:34:18.005: Theme directory 32@2x/devices of theme Vimix-Doder-dark has no size field

blueman-applet 18.34.18 WARNING  PluginManager:147 __load_plugin: Not loading PPPSupport because its conflict has higher priority
blueman-applet 18.34.18 WARNING  PluginManager:147 __load_plugin: Not loading DhcpClient because its conflict has higher priority
blueman-tray version 2.1.3 starting
There is an instance already running

(blueman-tray:329863): Gtk-WARNING **: 18:34:18.795: Theme directory 32@2x/devices of theme Vimix-Doder-dark has no size field


(blueman-tray:329863): Gdk-CRITICAL **: 18:34:18.822: gdk_window_thaw_toplevel_updates: assertion 'window->update_and_descendants_freeze_count > 0' failed
[0m[31m2020-06-01 18:34:40,825 [1m[31mlibqtile qtile.py:main():L153 [0m Qtile crashed
Traceback (most recent call last):
  File "/usr/lib/python3.8/site-packages/libqtile/scripts/qtile.py", line 151, in main
    q.loop()
  File "/usr/lib/python3.8/site-packages/libqtile/core/session_manager.py", line 48, in loop
    self.qtile.loop()
  File "/usr/lib/python3.8/site-packages/libqtile/ipc.py", line 234, in __exit__
    self.close()
  File "/usr/lib/python3.8/site-packages/libqtile/ipc.py", line 252, in close
    self.loop.run_until_complete(self.server.wait_closed())
  File "/usr/lib/python3.8/asyncio/base_events.py", line 591, in run_until_complete
    self._check_closed()
  File "/usr/lib/python3.8/asyncio/base_events.py", line 508, in _check_closed
    raise RuntimeError('Event loop is closed')
RuntimeError: Event loop is closed[0m
Gdk-Message: 18:34:40.894: blueman-tray: Fatal IO error 11 (Recurso no disponible temporalmente) on X server :0.

Gdk-Message: 18:34:40.895: nm-applet: Fatal IO error 11 (Recurso no disponible temporalmente) on X server :0.

Gdk-Message: 18:34:40.895: deadd-notification-center: Fatal IO error 11 (Recurso no disponible temporalmente) on X server :0.

Gdk-Message: 18:34:40.896: blueman-applet: Fatal IO error 11 (Recurso no disponible temporalmente) on X server :0.

XIO:  fatal IO error 11 (Recurso no disponible temporalmente) on X server ":0"
      after 4866 requests (4516 known processed) with 1 events remaining.
[0m[33m2020-06-01 18:34:49,843 [1m[33mlibqtile pacman.py:__init__():L38 [0m Pacman is deprecated, please use CheckUpdates[0m
[0m[33m2020-06-01 18:34:49,990 [1m[33mlibqtile pacman.py:__init__():L38 [0m Pacman is deprecated, please use CheckUpdates[0m
[0m[33m2020-06-01 18:34:49,993 [1m[33mlibqtile pacman.py:__init__():L38 [0m Pacman is deprecated, please use CheckUpdates[0m
[ 01/06/20 18:34:50.347 parse_config_libconfig WARN ] Option `no-dock-shadow` is deprecated, and will be removed. Please use the wintype option `shadow` of `dock` instead.
[ 01/06/20 18:34:50.347 parse_config_libconfig WARN ] Option `no-dnd-shadow` is deprecated, and will be removed. Please use the wintype option `shadow` of `dnd` instead.
[ 01/06/20 18:34:50.347 parse_config_libconfig WARN ] Option `menu-opacity` is deprecated, and will be removed.Please use the wintype option `opacity` of `popup_menu` and `dropdown_menu` instead.
[ 01/06/20 18:34:50.347 parse_config_libconfig WARN ] vsync option will take a boolean from now on. "opengl-swc" is interpreted as "true" for compatibility, but this will stop working soon
[ 01/06/20 18:34:50.347 parse_config_libconfig WARN ] glx-swap-method has been deprecated since v6, your setting "exchange" should be replaced by `use-damage = true`.
[ 01/06/20 18:34:50.347 parse_config_libconfig WARN ] "clear-shadow" is removed as an option, and is always enabled now. Consider removing it from your config file
[ 01/06/20 18:34:50.347 session_init WARN ] This compositor has been renamed to "picom", the "compton" binary will not be installed in the future.

(nitrogen:330599): Gtk-WARNING **: 18:34:50.413: Unable to locate theme engine in module_path: "murrine",

(nitrogen:330599): Gtk-WARNING **: 18:34:50.414: Unable to locate theme engine in module_path: "murrine",

(nitrogen:330599): Gtk-WARNING **: 18:34:50.414: Unable to locate theme engine in module_path: "murrine",

(nitrogen:330599): Gtk-WARNING **: 18:34:50.418: Unable to locate theme engine in module_path: "murrine",

(nitrogen:330599): Gtk-WARNING **: 18:34:50.418: Unable to locate theme engine in module_path: "murrine",

(nitrogen:330599): Gtk-WARNING **: 18:34:50.418: Unable to locate theme engine in module_path: "murrine",

(nitrogen:330599): Gtk-WARNING **: 18:34:50.421: Unable to locate theme engine in module_path: "murrine",

(nitrogen:330599): Gtk-WARNING **: 18:34:50.421: Unable to locate theme engine in module_path: "murrine",

(nitrogen:330599): Gtk-WARNING **: 18:34:50.421: Unable to locate theme engine in module_path: "murrine",

(nitrogen:330599): Gtk-WARNING **: 18:34:50.421: Unable to locate theme engine in module_path: "murrine",

(nitrogen:330599): Gtk-WARNING **: 18:34:50.422: Unable to locate theme engine in module_path: "murrine",
[ 01/06/20 18:34:50.482 swopti_init WARN ] --sw-opti is going to be deprecated. If you get real benefits from using this option, please open an issue to let us know.

(nm-applet:330601): Gtk-WARNING **: 18:34:50.791: Theme directory 32@2x/devices of theme Vimix-Doder-dark has no size field


(nitrogen:330599): Gtk-WARNING **: 18:34:50.821: Unable to locate theme engine in module_path: "murrine",

(nitrogen:330599): Gtk-WARNING **: 18:34:50.821: Unable to locate theme engine in module_path: "murrine",

(nitrogen:330599): Gtk-WARNING **: 18:34:50.821: Unable to locate theme engine in module_path: "murrine",

(nitrogen:330599): Gtk-WARNING **: 18:34:50.823: Unable to locate theme engine in module_path: "murrine",

(nitrogen:330599): Gtk-WARNING **: 18:34:50.823: Unable to locate theme engine in module_path: "murrine",

(nitrogen:330599): Gtk-WARNING **: 18:34:50.824: Unable to locate theme engine in module_path: "murrine",

(nitrogen:330599): Gtk-WARNING **: 18:34:50.825: Unable to locate theme engine in module_path: "murrine",

(nitrogen:330599): Gtk-WARNING **: 18:34:50.825: Unable to locate theme engine in module_path: "murrine",

(nitrogen:330599): Gtk-WARNING **: 18:34:50.825: Unable to locate theme engine in module_path: "murrine",

(nitrogen:330599): Gtk-WARNING **: 18:34:50.825: Unable to locate theme engine in module_path: "murrine",

(nitrogen:330599): Gtk-WARNING **: 18:34:50.826: Unable to locate theme engine in module_path: "murrine",

(blueman-applet:330602): Gtk-WARNING **: 18:34:50.886: Theme directory 32@2x/devices of theme Vimix-Doder-dark has no size field

blueman-applet 18.34.50 WARNING  PluginManager:147 __load_plugin: Not loading PPPSupport because its conflict has higher priority
blueman-applet 18.34.50 WARNING  PluginManager:147 __load_plugin: Not loading DhcpClient because its conflict has higher priority
blueman-tray version 2.1.3 starting
There is an instance already running

(blueman-tray:330683): Gtk-WARNING **: 18:34:51.603: Theme directory 32@2x/devices of theme Vimix-Doder-dark has no size field


(blueman-tray:330683): Gdk-CRITICAL **: 18:34:51.655: gdk_window_thaw_toplevel_updates: assertion 'window->update_and_descendants_freeze_count > 0' failed
[0m[31m2020-06-01 18:36:54,520 [1m[31mlibqtile qtile.py:main():L153 [0m Qtile crashed
Traceback (most recent call last):
  File "/usr/lib/python3.8/site-packages/libqtile/scripts/qtile.py", line 151, in main
    q.loop()
  File "/usr/lib/python3.8/site-packages/libqtile/core/session_manager.py", line 48, in loop
    self.qtile.loop()
  File "/usr/lib/python3.8/site-packages/libqtile/ipc.py", line 234, in __exit__
    self.close()
  File "/usr/lib/python3.8/site-packages/libqtile/ipc.py", line 252, in close
    self.loop.run_until_complete(self.server.wait_closed())
  File "/usr/lib/python3.8/asyncio/base_events.py", line 591, in run_until_complete
    self._check_closed()
  File "/usr/lib/python3.8/asyncio/base_events.py", line 508, in _check_closed
    raise RuntimeError('Event loop is closed')
RuntimeError: Event loop is closed[0m
X connection to :0 broken (explicit kill or server shutdown).
Gdk-Message: 18:36:54.585: deadd-notification-center: Fatal IO error 11 (Recurso no disponible temporalmente) on X server :0.

Gdk-Message: 18:36:54.585: blueman-applet: Fatal IO error 11 (Recurso no disponible temporalmente) on X server :0.

Gdk-Message: 18:36:54.585: nm-applet: Fatal IO error 11 (Recurso no disponible temporalmente) on X server :0.

Gdk-Message: 18:36:54.586: blueman-tray: Fatal IO error 11 (Recurso no disponible temporalmente) on X server :0.

[0m[33m2020-06-01 18:37:03,681 [1m[33mlibqtile pacman.py:__init__():L38 [0m Pacman is deprecated, please use CheckUpdates[0m
[0m[33m2020-06-01 18:37:03,830 [1m[33mlibqtile pacman.py:__init__():L38 [0m Pacman is deprecated, please use CheckUpdates[0m
[0m[33m2020-06-01 18:37:03,832 [1m[33mlibqtile pacman.py:__init__():L38 [0m Pacman is deprecated, please use CheckUpdates[0m
[ 01/06/20 18:37:04.214 parse_config_libconfig WARN ] Option `no-dock-shadow` is deprecated, and will be removed. Please use the wintype option `shadow` of `dock` instead.
[ 01/06/20 18:37:04.214 parse_config_libconfig WARN ] Option `no-dnd-shadow` is deprecated, and will be removed. Please use the wintype option `shadow` of `dnd` instead.
[ 01/06/20 18:37:04.214 parse_config_libconfig WARN ] Option `menu-opacity` is deprecated, and will be removed.Please use the wintype option `opacity` of `popup_menu` and `dropdown_menu` instead.
[ 01/06/20 18:37:04.214 parse_config_libconfig WARN ] vsync option will take a boolean from now on. "opengl-swc" is interpreted as "true" for compatibility, but this will stop working soon
[ 01/06/20 18:37:04.214 parse_config_libconfig WARN ] glx-swap-method has been deprecated since v6, your setting "exchange" should be replaced by `use-damage = true`.
[ 01/06/20 18:37:04.214 parse_config_libconfig WARN ] "clear-shadow" is removed as an option, and is always enabled now. Consider removing it from your config file
[ 01/06/20 18:37:04.214 session_init WARN ] This compositor has been renamed to "picom", the "compton" binary will not be installed in the future.

(nitrogen:333346): Gtk-WARNING **: 18:37:04.281: Unable to locate theme engine in module_path: "murrine",

(nitrogen:333346): Gtk-WARNING **: 18:37:04.281: Unable to locate theme engine in module_path: "murrine",

(nitrogen:333346): Gtk-WARNING **: 18:37:04.281: Unable to locate theme engine in module_path: "murrine",

(nitrogen:333346): Gtk-WARNING **: 18:37:04.284: Unable to locate theme engine in module_path: "murrine",

(nitrogen:333346): Gtk-WARNING **: 18:37:04.284: Unable to locate theme engine in module_path: "murrine",

(nitrogen:333346): Gtk-WARNING **: 18:37:04.284: Unable to locate theme engine in module_path: "murrine",

(nitrogen:333346): Gtk-WARNING **: 18:37:04.291: Unable to locate theme engine in module_path: "murrine",

(nitrogen:333346): Gtk-WARNING **: 18:37:04.291: Unable to locate theme engine in module_path: "murrine",

(nitrogen:333346): Gtk-WARNING **: 18:37:04.292: Unable to locate theme engine in module_path: "murrine",

(nitrogen:333346): Gtk-WARNING **: 18:37:04.292: Unable to locate theme engine in module_path: "murrine",

(nitrogen:333346): Gtk-WARNING **: 18:37:04.292: Unable to locate theme engine in module_path: "murrine",
[ 01/06/20 18:37:04.320 swopti_init WARN ] --sw-opti is going to be deprecated. If you get real benefits from using this option, please open an issue to let us know.

(nm-applet:333348): Gtk-WARNING **: 18:37:04.659: Theme directory 32@2x/devices of theme Vimix-Doder-dark has no size field


(nitrogen:333346): Gtk-WARNING **: 18:37:04.743: Unable to locate theme engine in module_path: "murrine",

(nitrogen:333346): Gtk-WARNING **: 18:37:04.743: Unable to locate theme engine in module_path: "murrine",

(nitrogen:333346): Gtk-WARNING **: 18:37:04.743: Unable to locate theme engine in module_path: "murrine",

(nitrogen:333346): Gtk-WARNING **: 18:37:04.746: Unable to locate theme engine in module_path: "murrine",

(nitrogen:333346): Gtk-WARNING **: 18:37:04.746: Unable to locate theme engine in module_path: "murrine",

(nitrogen:333346): Gtk-WARNING **: 18:37:04.746: Unable to locate theme engine in module_path: "murrine",

(nitrogen:333346): Gtk-WARNING **: 18:37:04.747: Unable to locate theme engine in module_path: "murrine",

(nitrogen:333346): Gtk-WARNING **: 18:37:04.748: Unable to locate theme engine in module_path: "murrine",

(nitrogen:333346): Gtk-WARNING **: 18:37:04.748: Unable to locate theme engine in module_path: "murrine",

(nitrogen:333346): Gtk-WARNING **: 18:37:04.748: Unable to locate theme engine in module_path: "murrine",

(nitrogen:333346): Gtk-WARNING **: 18:37:04.748: Unable to locate theme engine in module_path: "murrine",

(blueman-applet:333349): Gtk-WARNING **: 18:37:04.782: Theme directory 32@2x/devices of theme Vimix-Doder-dark has no size field

blueman-applet 18.37.04 WARNING  PluginManager:147 __load_plugin: Not loading PPPSupport because its conflict has higher priority
blueman-applet 18.37.04 WARNING  PluginManager:147 __load_plugin: Not loading DhcpClient because its conflict has higher priority
blueman-tray version 2.1.3 starting
There is an instance already running

(blueman-tray:333431): Gtk-WARNING **: 18:37:05.580: Theme directory 32@2x/devices of theme Vimix-Doder-dark has no size field


(blueman-tray:333431): Gdk-CRITICAL **: 18:37:05.602: gdk_window_thaw_toplevel_updates: assertion 'window->update_and_descendants_freeze_count > 0' failed
[0m[31m2020-06-01 18:45:01,701 [1m[31mlibqtile qtile.py:main():L153 [0m Qtile crashed
Traceback (most recent call last):
  File "/usr/lib/python3.8/site-packages/libqtile/scripts/qtile.py", line 151, in main
    q.loop()
  File "/usr/lib/python3.8/site-packages/libqtile/core/session_manager.py", line 48, in loop
    self.qtile.loop()
  File "/usr/lib/python3.8/site-packages/libqtile/ipc.py", line 234, in __exit__
    self.close()
  File "/usr/lib/python3.8/site-packages/libqtile/ipc.py", line 252, in close
    self.loop.run_until_complete(self.server.wait_closed())
  File "/usr/lib/python3.8/asyncio/base_events.py", line 591, in run_until_complete
    self._check_closed()
  File "/usr/lib/python3.8/asyncio/base_events.py", line 508, in _check_closed
    raise RuntimeError('Event loop is closed')
RuntimeError: Event loop is closed[0m
Gdk-Message: 18:45:01.762: blueman-tray: Fatal IO error 11 (Recurso no disponible temporalmente) on X server :0.

[ 01/06/20 18:45:01.762 handle_queued_x_events FATAL ERROR ] X11 server connection broke (error 1)
Gdk-Message: 18:45:01.762: nm-applet: Fatal IO error 11 (Recurso no disponible temporalmente) on X server :0.

Gdk-Message: 18:45:01.762: deadd-notification-center: Fatal IO error 11 (Recurso no disponible temporalmente) on X server :0.

Gdk-Message: 18:45:01.763: blueman-applet: Fatal IO error 11 (Recurso no disponible temporalmente) on X server :0.

[0m[33m2020-06-01 18:45:11,026 [1m[33mlibqtile pacman.py:__init__():L38 [0m Pacman is deprecated, please use CheckUpdates[0m
[0m[33m2020-06-01 18:45:11,185 [1m[33mlibqtile pacman.py:__init__():L38 [0m Pacman is deprecated, please use CheckUpdates[0m
[0m[33m2020-06-01 18:45:11,187 [1m[33mlibqtile pacman.py:__init__():L38 [0m Pacman is deprecated, please use CheckUpdates[0m
[ 01/06/20 18:45:11.540 parse_config_libconfig WARN ] Option `no-dock-shadow` is deprecated, and will be removed. Please use the wintype option `shadow` of `dock` instead.
[ 01/06/20 18:45:11.541 parse_config_libconfig WARN ] Option `no-dnd-shadow` is deprecated, and will be removed. Please use the wintype option `shadow` of `dnd` instead.
[ 01/06/20 18:45:11.541 parse_config_libconfig WARN ] Option `menu-opacity` is deprecated, and will be removed.Please use the wintype option `opacity` of `popup_menu` and `dropdown_menu` instead.
[ 01/06/20 18:45:11.541 parse_config_libconfig WARN ] vsync option will take a boolean from now on. "opengl-swc" is interpreted as "true" for compatibility, but this will stop working soon
[ 01/06/20 18:45:11.541 parse_config_libconfig WARN ] glx-swap-method has been deprecated since v6, your setting "exchange" should be replaced by `use-damage = true`.
[ 01/06/20 18:45:11.541 parse_config_libconfig WARN ] "clear-shadow" is removed as an option, and is always enabled now. Consider removing it from your config file
[ 01/06/20 18:45:11.541 session_init WARN ] This compositor has been renamed to "picom", the "compton" binary will not be installed in the future.

(nitrogen:342798): Gtk-WARNING **: 18:45:11.650: Unable to locate theme engine in module_path: "murrine",

(nitrogen:342798): Gtk-WARNING **: 18:45:11.650: Unable to locate theme engine in module_path: "murrine",

(nitrogen:342798): Gtk-WARNING **: 18:45:11.650: Unable to locate theme engine in module_path: "murrine",

(nitrogen:342798): Gtk-WARNING **: 18:45:11.653: Unable to locate theme engine in module_path: "murrine",

(nitrogen:342798): Gtk-WARNING **: 18:45:11.653: Unable to locate theme engine in module_path: "murrine",

(nitrogen:342798): Gtk-WARNING **: 18:45:11.653: Unable to locate theme engine in module_path: "murrine",

(nitrogen:342798): Gtk-WARNING **: 18:45:11.654: Unable to locate theme engine in module_path: "murrine",

(nitrogen:342798): Gtk-WARNING **: 18:45:11.655: Unable to locate theme engine in module_path: "murrine",

(nitrogen:342798): Gtk-WARNING **: 18:45:11.655: Unable to locate theme engine in module_path: "murrine",

(nitrogen:342798): Gtk-WARNING **: 18:45:11.655: Unable to locate theme engine in module_path: "murrine",

(nitrogen:342798): Gtk-WARNING **: 18:45:11.656: Unable to locate theme engine in module_path: "murrine",
[ 01/06/20 18:45:11.666 swopti_init WARN ] --sw-opti is going to be deprecated. If you get real benefits from using this option, please open an issue to let us know.

(nm-applet:342800): Gtk-WARNING **: 18:45:11.979: Theme directory 32@2x/devices of theme Vimix-Doder-dark has no size field


(nitrogen:342798): Gtk-WARNING **: 18:45:12.017: Unable to locate theme engine in module_path: "murrine",

(nitrogen:342798): Gtk-WARNING **: 18:45:12.018: Unable to locate theme engine in module_path: "murrine",

(nitrogen:342798): Gtk-WARNING **: 18:45:12.018: Unable to locate theme engine in module_path: "murrine",

(nitrogen:342798): Gtk-WARNING **: 18:45:12.020: Unable to locate theme engine in module_path: "murrine",

(nitrogen:342798): Gtk-WARNING **: 18:45:12.020: Unable to locate theme engine in module_path: "murrine",

(nitrogen:342798): Gtk-WARNING **: 18:45:12.021: Unable to locate theme engine in module_path: "murrine",

(nitrogen:342798): Gtk-WARNING **: 18:45:12.022: Unable to locate theme engine in module_path: "murrine",

(nitrogen:342798): Gtk-WARNING **: 18:45:12.022: Unable to locate theme engine in module_path: "murrine",

(nitrogen:342798): Gtk-WARNING **: 18:45:12.022: Unable to locate theme engine in module_path: "murrine",

(nitrogen:342798): Gtk-WARNING **: 18:45:12.022: Unable to locate theme engine in module_path: "murrine",

(nitrogen:342798): Gtk-WARNING **: 18:45:12.023: Unable to locate theme engine in module_path: "murrine",

(blueman-applet:342801): Gtk-WARNING **: 18:45:12.120: Theme directory 32@2x/devices of theme Vimix-Doder-dark has no size field

blueman-applet 18.45.12 WARNING  PluginManager:147 __load_plugin: Not loading PPPSupport because its conflict has higher priority
blueman-applet 18.45.12 WARNING  PluginManager:147 __load_plugin: Not loading DhcpClient because its conflict has higher priority
blueman-tray version 2.1.3 starting
There is an instance already running

(blueman-tray:342884): Gtk-WARNING **: 18:45:12.827: Theme directory 32@2x/devices of theme Vimix-Doder-dark has no size field


(blueman-tray:342884): Gdk-CRITICAL **: 18:45:12.848: gdk_window_thaw_toplevel_updates: assertion 'window->update_and_descendants_freeze_count > 0' failed
[0m[31m2020-06-01 18:47:21,872 [1m[31mlibqtile qtile.py:main():L153 [0m Qtile crashed
Traceback (most recent call last):
  File "/usr/lib/python3.8/site-packages/libqtile/scripts/qtile.py", line 151, in main
    q.loop()
  File "/usr/lib/python3.8/site-packages/libqtile/core/session_manager.py", line 48, in loop
    self.qtile.loop()
  File "/usr/lib/python3.8/site-packages/libqtile/ipc.py", line 234, in __exit__
    self.close()
  File "/usr/lib/python3.8/site-packages/libqtile/ipc.py", line 252, in close
    self.loop.run_until_complete(self.server.wait_closed())
  File "/usr/lib/python3.8/asyncio/base_events.py", line 591, in run_until_complete
    self._check_closed()
  File "/usr/lib/python3.8/asyncio/base_events.py", line 508, in _check_closed
    raise RuntimeError('Event loop is closed')
RuntimeError: Event loop is closed[0m
X connection to :0 broken (explicit kill or server shutdown).
Gdk-Message: 18:47:21.943: blueman-tray: Fatal IO error 11 (Recurso no disponible temporalmente) on X server :0.

Gdk-Message: 18:47:21.943: blueman-applet: Fatal IO error 11 (Recurso no disponible temporalmente) on X server :0.

Gdk-Message: 18:47:21.945: deadd-notification-center: Fatal IO error 11 (Recurso no disponible temporalmente) on X server :0.

Gdk-Message: 18:47:21.945: nm-applet: Fatal IO error 11 (Recurso no disponible temporalmente) on X server :0.

Invalid MIT-MAGIC-COOKIE-1 keyTraceback (most recent call last):
  File "/usr/bin/qtile", line 11, in <module>
    load_entry_point('qtile==0.15.1.dev122+gaaebfb55', 'console_scripts', 'qtile')()
  File "/usr/lib/python3.8/site-packages/libqtile/scripts/qtile.py", line 149, in main
    q = make_qtile()
  File "/usr/lib/python3.8/site-packages/libqtile/scripts/qtile.py", line 110, in make_qtile
    kore = xcore.XCore()
  File "/usr/lib/python3.8/site-packages/libqtile/backend/x11/xcore.py", line 67, in __init__
    self.conn = xcbq.Connection(display_name)
  File "/usr/lib/python3.8/site-packages/libqtile/backend/x11/xcbq.py", line 839, in __init__
    self.conn = xcffib.connect(display=display)
  File "/usr/lib/python3.8/site-packages/xcffib/__init__.py", line 527, in __init__
    self.invalid()
  File "/usr/lib/python3.8/site-packages/xcffib/__init__.py", line 559, in invalid
    raise ConnectionException(err)
xcffib.ConnectionException: xcb connection errors because of socket, pipe and other stream errors.
[0m[33m2020-06-01 18:47:56,068 [1m[33mlibqtile pacman.py:__init__():L38 [0m Pacman is deprecated, please use CheckUpdates[0m
[0m[33m2020-06-01 18:47:56,219 [1m[33mlibqtile pacman.py:__init__():L38 [0m Pacman is deprecated, please use CheckUpdates[0m
[0m[33m2020-06-01 18:47:56,221 [1m[33mlibqtile pacman.py:__init__():L38 [0m Pacman is deprecated, please use CheckUpdates[0m
[ 01/06/20 18:47:56.579 parse_config_libconfig WARN ] Option `no-dock-shadow` is deprecated, and will be removed. Please use the wintype option `shadow` of `dock` instead.
[ 01/06/20 18:47:56.579 parse_config_libconfig WARN ] Option `no-dnd-shadow` is deprecated, and will be removed. Please use the wintype option `shadow` of `dnd` instead.
[ 01/06/20 18:47:56.579 parse_config_libconfig WARN ] Option `menu-opacity` is deprecated, and will be removed.Please use the wintype option `opacity` of `popup_menu` and `dropdown_menu` instead.
[ 01/06/20 18:47:56.579 parse_config_libconfig WARN ] vsync option will take a boolean from now on. "opengl-swc" is interpreted as "true" for compatibility, but this will stop working soon
[ 01/06/20 18:47:56.598 parse_config_libconfig WARN ] glx-swap-method has been deprecated since v6, your setting "exchange" should be replaced by `use-damage = true`.
[ 01/06/20 18:47:56.598 parse_config_libconfig WARN ] "clear-shadow" is removed as an option, and is always enabled now. Consider removing it from your config file
[ 01/06/20 18:47:56.598 session_init WARN ] This compositor has been renamed to "picom", the "compton" binary will not be installed in the future.

(nitrogen:345664): Gtk-WARNING **: 18:47:56.663: Unable to locate theme engine in module_path: "murrine",

(nitrogen:345664): Gtk-WARNING **: 18:47:56.663: Unable to locate theme engine in module_path: "murrine",

(nitrogen:345664): Gtk-WARNING **: 18:47:56.663: Unable to locate theme engine in module_path: "murrine",

(nitrogen:345664): Gtk-WARNING **: 18:47:56.672: Unable to locate theme engine in module_path: "murrine",

(nitrogen:345664): Gtk-WARNING **: 18:47:56.673: Unable to locate theme engine in module_path: "murrine",

(nitrogen:345664): Gtk-WARNING **: 18:47:56.674: Unable to locate theme engine in module_path: "murrine",

(nitrogen:345664): Gtk-WARNING **: 18:47:56.684: Unable to locate theme engine in module_path: "murrine",

(nitrogen:345664): Gtk-WARNING **: 18:47:56.684: Unable to locate theme engine in module_path: "murrine",

(nitrogen:345664): Gtk-WARNING **: 18:47:56.684: Unable to locate theme engine in module_path: "murrine",

(nitrogen:345664): Gtk-WARNING **: 18:47:56.685: Unable to locate theme engine in module_path: "murrine",

(nitrogen:345664): Gtk-WARNING **: 18:47:56.685: Unable to locate theme engine in module_path: "murrine",
[ 01/06/20 18:47:56.715 swopti_init WARN ] --sw-opti is going to be deprecated. If you get real benefits from using this option, please open an issue to let us know.

(nm-applet:345666): Gtk-WARNING **: 18:47:56.942: Theme directory 32@2x/devices of theme Vimix-Doder-dark has no size field


(nitrogen:345664): Gtk-WARNING **: 18:47:57.074: Unable to locate theme engine in module_path: "murrine",

(nitrogen:345664): Gtk-WARNING **: 18:47:57.074: Unable to locate theme engine in module_path: "murrine",

(nitrogen:345664): Gtk-WARNING **: 18:47:57.074: Unable to locate theme engine in module_path: "murrine",

(nitrogen:345664): Gtk-WARNING **: 18:47:57.075: Unable to locate theme engine in module_path: "murrine",

(nitrogen:345664): Gtk-WARNING **: 18:47:57.075: Unable to locate theme engine in module_path: "murrine",

(nitrogen:345664): Gtk-WARNING **: 18:47:57.075: Unable to locate theme engine in module_path: "murrine",

(nitrogen:345664): Gtk-WARNING **: 18:47:57.076: Unable to locate theme engine in module_path: "murrine",

(nitrogen:345664): Gtk-WARNING **: 18:47:57.076: Unable to locate theme engine in module_path: "murrine",

(nitrogen:345664): Gtk-WARNING **: 18:47:57.076: Unable to locate theme engine in module_path: "murrine",

(nitrogen:345664): Gtk-WARNING **: 18:47:57.076: Unable to locate theme engine in module_path: "murrine",

(nitrogen:345664): Gtk-WARNING **: 18:47:57.077: Unable to locate theme engine in module_path: "murrine",

(blueman-applet:345667): Gtk-WARNING **: 18:47:57.155: Theme directory 32@2x/devices of theme Vimix-Doder-dark has no size field

blueman-applet 18.47.57 WARNING  PluginManager:147 __load_plugin: Not loading PPPSupport because its conflict has higher priority
blueman-applet 18.47.57 WARNING  PluginManager:147 __load_plugin: Not loading DhcpClient because its conflict has higher priority
blueman-tray version 2.1.3 starting
There is an instance already running

(blueman-tray:345749): Gtk-WARNING **: 18:47:57.825: Theme directory 32@2x/devices of theme Vimix-Doder-dark has no size field


(blueman-tray:345749): Gdk-CRITICAL **: 18:47:57.854: gdk_window_thaw_toplevel_updates: assertion 'window->update_and_descendants_freeze_count > 0' failed
[0m[31m2020-06-01 18:50:31,169 [1m[31mlibqtile manager.py:handle_exception():L76 [0m xcb connection errors because of socket, pipe and other stream errors.
Traceback (most recent call last):
  File "/usr/lib/python3.8/asyncio/events.py", line 81, in _run
    self._context.run(self._callback, *self._args)
  File "/usr/lib/python3.8/site-packages/libqtile/core/manager.py", line 876, in f
    self.conn.flush()
  File "/usr/lib/python3.8/site-packages/libqtile/backend/x11/xcbq.py", line 955, in flush
    return self.conn.flush()
  File "/usr/lib/python3.8/site-packages/xcffib/__init__.py", line 573, in wrapper
    self.invalid()
  File "/usr/lib/python3.8/site-packages/xcffib/__init__.py", line 559, in invalid
    raise ConnectionException(err)
xcffib.ConnectionException: xcb connection errors because of socket, pipe and other stream errors.[0m
[0m[31m2020-06-01 18:50:31,172 [1m[31mlibqtile xcore.py:_xpoll():L270 [0m Shutting down due to X connection error XCB_CONN_ERROR (1)
Traceback (most recent call last):
  File "/usr/lib/python3.8/site-packages/libqtile/backend/x11/xcore.py", line 231, in _xpoll
    event = self.conn.conn.poll_for_event()
  File "/usr/lib/python3.8/site-packages/xcffib/__init__.py", line 569, in wrapper
    self.invalid()
  File "/usr/lib/python3.8/site-packages/xcffib/__init__.py", line 559, in invalid
    raise ConnectionException(err)
xcffib.ConnectionException: xcb connection errors because of socket, pipe and other stream errors.[0m
[0m[31m2020-06-01 18:50:31,182 [1m[31mlibqtile manager.py:get_interesting_pid():L593 [0m Got an exception in getting the window pid
Traceback (most recent call last):
  File "/usr/lib/python3.8/site-packages/libqtile/backend/x11/xcore.py", line 231, in _xpoll
    event = self.conn.conn.poll_for_event()
  File "/usr/lib/python3.8/site-packages/xcffib/__init__.py", line 569, in wrapper
    self.invalid()
  File "/usr/lib/python3.8/site-packages/xcffib/__init__.py", line 559, in invalid
    raise ConnectionException(err)
xcffib.ConnectionException: xcb connection errors because of socket, pipe and other stream errors.

During handling of the above exception, another exception occurred:

Traceback (most recent call last):
  File "/usr/lib/python3.8/site-packages/libqtile/core/manager.py", line 591, in get_interesting_pid
    return win.window.get_net_wm_pid()
  File "/usr/lib/python3.8/site-packages/libqtile/backend/x11/xcbq.py", line 611, in get_net_wm_pid
    r = self.get_property("_NET_WM_PID", unpack=int)
  File "/usr/lib/python3.8/site-packages/libqtile/backend/x11/xcbq.py", line 704, in get_property
    r = self.conn.conn.core.GetProperty(
  File "/usr/lib/python3.8/site-packages/xcffib/xproto.py", line 2720, in GetProperty
    return self.send_request(20, buf, GetPropertyCookie, is_checked=is_checked)
  File "/usr/lib/python3.8/site-packages/xcffib/__init__.py", line 391, in send_request
    seq = self.conn.send_request(flags, xcb_parts + 2, xcb_req)
  File "/usr/lib/python3.8/site-packages/xcffib/__init__.py", line 569, in wrapper
    self.invalid()
  File "/usr/lib/python3.8/site-packages/xcffib/__init__.py", line 559, in invalid
    raise ConnectionException(err)
xcffib.ConnectionException: xcb connection errors because of socket, pipe and other stream errors.[0m
[0m[31m2020-06-01 18:50:31,185 [1m[31mlibqtile manager.py:handle_exception():L76 [0m xcb connection errors because of socket, pipe and other stream errors.
Traceback (most recent call last):
  File "/usr/lib/python3.8/asyncio/events.py", line 81, in _run
    self._context.run(self._callback, *self._args)
  File "/usr/lib/python3.8/site-packages/libqtile/core/manager.py", line 890, in f
    self.conn.flush()
  File "/usr/lib/python3.8/site-packages/libqtile/backend/x11/xcbq.py", line 955, in flush
    return self.conn.flush()
  File "/usr/lib/python3.8/site-packages/xcffib/__init__.py", line 569, in wrapper
    self.invalid()
  File "/usr/lib/python3.8/site-packages/xcffib/__init__.py", line 559, in invalid
    raise ConnectionException(err)
xcffib.ConnectionException: xcb connection errors because of socket, pipe and other stream errors.[0m
[0m[31m2020-06-01 18:50:31,186 [1m[31mlibqtile manager.py:get_interesting_pid():L593 [0m Got an exception in getting the window pid
Traceback (most recent call last):
  File "/usr/lib/python3.8/site-packages/libqtile/core/manager.py", line 591, in get_interesting_pid
    return win.window.get_net_wm_pid()
  File "/usr/lib/python3.8/site-packages/libqtile/backend/x11/xcbq.py", line 611, in get_net_wm_pid
    r = self.get_property("_NET_WM_PID", unpack=int)
  File "/usr/lib/python3.8/site-packages/libqtile/backend/x11/xcbq.py", line 704, in get_property
    r = self.conn.conn.core.GetProperty(
  File "/usr/lib/python3.8/site-packages/xcffib/xproto.py", line 2720, in GetProperty
    return self.send_request(20, buf, GetPropertyCookie, is_checked=is_checked)
  File "/usr/lib/python3.8/site-packages/xcffib/__init__.py", line 391, in send_request
    seq = self.conn.send_request(flags, xcb_parts + 2, xcb_req)
  File "/usr/lib/python3.8/site-packages/xcffib/__init__.py", line 569, in wrapper
    self.invalid()
  File "/usr/lib/python3.8/site-packages/xcffib/__init__.py", line 559, in invalid
    raise ConnectionException(err)
xcffib.ConnectionException: xcb connection errors because of socket, pipe and other stream errors.[0m
[0m[31m2020-06-01 18:50:31,187 [1m[31mlibqtile manager.py:get_interesting_pid():L593 [0m Got an exception in getting the window pid
Traceback (most recent call last):
  File "/usr/lib/python3.8/site-packages/libqtile/core/manager.py", line 591, in get_interesting_pid
    return win.window.get_net_wm_pid()
  File "/usr/lib/python3.8/site-packages/libqtile/backend/x11/xcbq.py", line 611, in get_net_wm_pid
    r = self.get_property("_NET_WM_PID", unpack=int)
  File "/usr/lib/python3.8/site-packages/libqtile/backend/x11/xcbq.py", line 704, in get_property
    r = self.conn.conn.core.GetProperty(
  File "/usr/lib/python3.8/site-packages/xcffib/xproto.py", line 2720, in GetProperty
    return self.send_request(20, buf, GetPropertyCookie, is_checked=is_checked)
  File "/usr/lib/python3.8/site-packages/xcffib/__init__.py", line 391, in send_request
    seq = self.conn.send_request(flags, xcb_parts + 2, xcb_req)
  File "/usr/lib/python3.8/site-packages/xcffib/__init__.py", line 569, in wrapper
    self.invalid()
  File "/usr/lib/python3.8/site-packages/xcffib/__init__.py", line 559, in invalid
    raise ConnectionException(err)
xcffib.ConnectionException: xcb connection errors because of socket, pipe and other stream errors.[0m
[0m[31m2020-06-01 18:50:31,199 [1m[31mlibqtile manager.py:finalize():L303 [0m exception during finalize
Traceback (most recent call last):
  File "/usr/lib/python3.8/site-packages/libqtile/core/manager.py", line 293, in finalize
    widget.finalize()
  File "/usr/lib/python3.8/site-packages/libqtile/widget/base.py", line 208, in finalize
    self.drawer.finalize()
  File "/usr/lib/python3.8/site-packages/libqtile/drawer.py", line 247, in finalize
    self.qtile.conn.conn.core.FreeGC(self.gc)
  File "/usr/lib/python3.8/site-packages/xcffib/xproto.py", line 3027, in FreeGC
    return self.send_request(60, buf, is_checked=is_checked)
  File "/usr/lib/python3.8/site-packages/xcffib/__init__.py", line 391, in send_request
    seq = self.conn.send_request(flags, xcb_parts + 2, xcb_req)
  File "/usr/lib/python3.8/site-packages/xcffib/__init__.py", line 569, in wrapper
    self.invalid()
  File "/usr/lib/python3.8/site-packages/xcffib/__init__.py", line 559, in invalid
    raise ConnectionException(err)
xcffib.ConnectionException: xcb connection errors because of socket, pipe and other stream errors.[0m
[0m[31m2020-06-01 18:50:31,200 [1m[31mlibqtile xcbq.py:disconnect():L950 [0m Failed to disconnect, connection already failed?[0m
[0m[31m2020-06-01 18:50:31,203 [1m[31mlibqtile qtile.py:main():L153 [0m Qtile crashed
Traceback (most recent call last):
  File "/usr/lib/python3.8/site-packages/libqtile/scripts/qtile.py", line 151, in main
    q.loop()
  File "/usr/lib/python3.8/site-packages/libqtile/core/session_manager.py", line 48, in loop
    self.qtile.loop()
  File "/usr/lib/python3.8/site-packages/libqtile/ipc.py", line 234, in __exit__
    self.close()
  File "/usr/lib/python3.8/site-packages/libqtile/ipc.py", line 252, in close
    self.loop.run_until_complete(self.server.wait_closed())
  File "/usr/lib/python3.8/asyncio/base_events.py", line 591, in run_until_complete
    self._check_closed()
  File "/usr/lib/python3.8/asyncio/base_events.py", line 508, in _check_closed
    raise RuntimeError('Event loop is closed')
RuntimeError: Event loop is closed[0m
[0m[33m2020-06-01 18:51:44,230 [1m[33mlibqtile pacman.py:__init__():L38 [0m Pacman is deprecated, please use CheckUpdates[0m
[0m[33m2020-06-01 18:51:44,391 [1m[33mlibqtile pacman.py:__init__():L38 [0m Pacman is deprecated, please use CheckUpdates[0m
[0m[33m2020-06-01 18:51:44,394 [1m[33mlibqtile pacman.py:__init__():L38 [0m Pacman is deprecated, please use CheckUpdates[0m
[ 01/06/20 18:51:44.827 parse_config_libconfig WARN ] Option `no-dock-shadow` is deprecated, and will be removed. Please use the wintype option `shadow` of `dock` instead.
[ 01/06/20 18:51:44.827 parse_config_libconfig WARN ] Option `no-dnd-shadow` is deprecated, and will be removed. Please use the wintype option `shadow` of `dnd` instead.
[ 01/06/20 18:51:44.827 parse_config_libconfig WARN ] Option `menu-opacity` is deprecated, and will be removed.Please use the wintype option `opacity` of `popup_menu` and `dropdown_menu` instead.
[ 01/06/20 18:51:44.827 parse_config_libconfig WARN ] vsync option will take a boolean from now on. "opengl-swc" is interpreted as "true" for compatibility, but this will stop working soon
[ 01/06/20 18:51:44.827 parse_config_libconfig WARN ] glx-swap-method has been deprecated since v6, your setting "exchange" should be replaced by `use-damage = true`.
[ 01/06/20 18:51:44.827 parse_config_libconfig WARN ] "clear-shadow" is removed as an option, and is always enabled now. Consider removing it from your config file
[ 01/06/20 18:51:44.828 session_init WARN ] This compositor has been renamed to "picom", the "compton" binary will not be installed in the future.
[ 01/06/20 18:51:44.962 swopti_init WARN ] --sw-opti is going to be deprecated. If you get real benefits from using this option, please open an issue to let us know.

(nitrogen:774): Gtk-WARNING **: 18:51:45.006: Unable to locate theme engine in module_path: "murrine",

(nitrogen:774): Gtk-WARNING **: 18:51:45.007: Unable to locate theme engine in module_path: "murrine",

(nitrogen:774): Gtk-WARNING **: 18:51:45.007: Unable to locate theme engine in module_path: "murrine",

(nitrogen:774): Gtk-WARNING **: 18:51:45.010: Unable to locate theme engine in module_path: "murrine",

(nitrogen:774): Gtk-WARNING **: 18:51:45.010: Unable to locate theme engine in module_path: "murrine",

(nitrogen:774): Gtk-WARNING **: 18:51:45.010: Unable to locate theme engine in module_path: "murrine",

(nitrogen:774): Gtk-WARNING **: 18:51:45.012: Unable to locate theme engine in module_path: "murrine",

(nitrogen:774): Gtk-WARNING **: 18:51:45.014: Unable to locate theme engine in module_path: "murrine",

(nitrogen:774): Gtk-WARNING **: 18:51:45.014: Unable to locate theme engine in module_path: "murrine",

(nitrogen:774): Gtk-WARNING **: 18:51:45.014: Unable to locate theme engine in module_path: "murrine",

(nitrogen:774): Gtk-WARNING **: 18:51:45.015: Unable to locate theme engine in module_path: "murrine",

(nm-applet:776): Gtk-WARNING **: 18:51:45.278: Theme directory 32@2x/devices of theme Vimix-Doder-dark has no size field


(nitrogen:774): Gtk-WARNING **: 18:51:45.528: Unable to locate theme engine in module_path: "murrine",

(nitrogen:774): Gtk-WARNING **: 18:51:45.528: Unable to locate theme engine in module_path: "murrine",

(nitrogen:774): Gtk-WARNING **: 18:51:45.528: Unable to locate theme engine in module_path: "murrine",

(nitrogen:774): Gtk-WARNING **: 18:51:45.531: Unable to locate theme engine in module_path: "murrine",

(nitrogen:774): Gtk-WARNING **: 18:51:45.531: Unable to locate theme engine in module_path: "murrine",

(nitrogen:774): Gtk-WARNING **: 18:51:45.531: Unable to locate theme engine in module_path: "murrine",

(nitrogen:774): Gtk-WARNING **: 18:51:45.533: Unable to locate theme engine in module_path: "murrine",

(nitrogen:774): Gtk-WARNING **: 18:51:45.533: Unable to locate theme engine in module_path: "murrine",

(nitrogen:774): Gtk-WARNING **: 18:51:45.533: Unable to locate theme engine in module_path: "murrine",

(nitrogen:774): Gtk-WARNING **: 18:51:45.533: Unable to locate theme engine in module_path: "murrine",

(nitrogen:774): Gtk-WARNING **: 18:51:45.534: Unable to locate theme engine in module_path: "murrine",

(blueman-applet:777): Gtk-WARNING **: 18:51:45.593: Theme directory 32@2x/devices of theme Vimix-Doder-dark has no size field

blueman-applet 18.51.45 WARNING  PluginManager:147 __load_plugin: Not loading PPPSupport because its conflict has higher priority
blueman-applet 18.51.45 WARNING  PluginManager:147 __load_plugin: Not loading DhcpClient because its conflict has higher priority
blueman-tray version 2.1.3 starting
There is an instance already running

(blueman-tray:915): Gtk-WARNING **: 18:51:46.315: Theme directory 32@2x/devices of theme Vimix-Doder-dark has no size field


(blueman-tray:915): Gdk-CRITICAL **: 18:51:46.352: gdk_window_thaw_toplevel_updates: assertion 'window->update_and_descendants_freeze_count > 0' failed
[0m[31m2020-06-01 18:52:09,003 [1m[31mlibqtile base.py:_wrapper():L294 [0m got exception from widget timer
Traceback (most recent call last):
  File "/usr/lib/python3.8/site-packages/libqtile/widget/base.py", line 292, in _wrapper
    method(*method_args)
  File "/usr/lib/python3.8/site-packages/libqtile/widget/base.py", line 451, in timer_setup
    update_interval = self.tick()
  File "/usr/lib/python3.8/site-packages/libqtile/widget/clock.py", line 73, in tick
    self.update(self.poll())
  File "/usr/lib/python3.8/site-packages/libqtile/widget/base.py", line 481, in update
    old_width = self.layout.width
  File "/usr/lib/python3.8/site-packages/libqtile/drawer.py", line 79, in width
    return self.layout.get_pixel_size()[0]
  File "/usr/lib/python3.8/site-packages/libqtile/pangocffi.py", line 125, in get_pixel_size
    pango.pango_layout_get_pixel_size(self._pointer, width, height)
TypeError: initializer for ctype 'PangoLayout *' must be a cdata pointer, not NoneType[0m
[0m[31m2020-06-01 18:52:09,004 [1m[31mlibqtile qtile.py:main():L153 [0m Qtile crashed
Traceback (most recent call last):
  File "/usr/lib/python3.8/site-packages/libqtile/scripts/qtile.py", line 151, in main
    q.loop()
  File "/usr/lib/python3.8/site-packages/libqtile/core/session_manager.py", line 48, in loop
    self.qtile.loop()
  File "/usr/lib/python3.8/site-packages/libqtile/ipc.py", line 234, in __exit__
    self.close()
  File "/usr/lib/python3.8/site-packages/libqtile/ipc.py", line 252, in close
    self.loop.run_until_complete(self.server.wait_closed())
  File "/usr/lib/python3.8/asyncio/base_events.py", line 591, in run_until_complete
    self._check_closed()
  File "/usr/lib/python3.8/asyncio/base_events.py", line 508, in _check_closed
    raise RuntimeError('Event loop is closed')
RuntimeError: Event loop is closed[0m
[0m[33m2020-06-01 18:52:24,488 [1m[33mlibqtile pacman.py:__init__():L38 [0m Pacman is deprecated, please use CheckUpdates[0m
[0m[33m2020-06-01 18:52:24,648 [1m[33mlibqtile pacman.py:__init__():L38 [0m Pacman is deprecated, please use CheckUpdates[0m
[0m[33m2020-06-01 18:52:24,651 [1m[33mlibqtile pacman.py:__init__():L38 [0m Pacman is deprecated, please use CheckUpdates[0m
[ 01/06/20 18:52:25.067 parse_config_libconfig WARN ] Option `no-dock-shadow` is deprecated, and will be removed. Please use the wintype option `shadow` of `dock` instead.
[ 01/06/20 18:52:25.067 parse_config_libconfig WARN ] Option `no-dnd-shadow` is deprecated, and will be removed. Please use the wintype option `shadow` of `dnd` instead.
[ 01/06/20 18:52:25.067 parse_config_libconfig WARN ] Option `menu-opacity` is deprecated, and will be removed.Please use the wintype option `opacity` of `popup_menu` and `dropdown_menu` instead.
[ 01/06/20 18:52:25.067 parse_config_libconfig WARN ] vsync option will take a boolean from now on. "opengl-swc" is interpreted as "true" for compatibility, but this will stop working soon
[ 01/06/20 18:52:25.067 parse_config_libconfig WARN ] glx-swap-method has been deprecated since v6, your setting "exchange" should be replaced by `use-damage = true`.
[ 01/06/20 18:52:25.067 parse_config_libconfig WARN ] "clear-shadow" is removed as an option, and is always enabled now. Consider removing it from your config file
[ 01/06/20 18:52:25.067 session_init WARN ] This compositor has been renamed to "picom", the "compton" binary will not be installed in the future.
[ 01/06/20 18:52:25.194 swopti_init WARN ] --sw-opti is going to be deprecated. If you get real benefits from using this option, please open an issue to let us know.
[0m[31m2020-06-01 18:52:25,213 [1m[31mlibqtile base.py:worker():L502 [0m problem polling to update widget yahooweather
Traceback (most recent call last):
  File "/usr/lib/python3.8/urllib/request.py", line 1350, in do_open
    h.request(req.get_method(), req.selector, req.data, headers,
  File "/usr/lib/python3.8/http/client.py", line 1240, in request
    self._send_request(method, url, body, headers, encode_chunked)
  File "/usr/lib/python3.8/http/client.py", line 1286, in _send_request
    self.endheaders(body, encode_chunked=encode_chunked)
  File "/usr/lib/python3.8/http/client.py", line 1235, in endheaders
    self._send_output(message_body, encode_chunked=encode_chunked)
  File "/usr/lib/python3.8/http/client.py", line 1006, in _send_output
    self.send(msg)
  File "/usr/lib/python3.8/http/client.py", line 946, in send
    self.connect()
  File "/usr/lib/python3.8/http/client.py", line 1402, in connect
    super().connect()
  File "/usr/lib/python3.8/http/client.py", line 917, in connect
    self.sock = self._create_connection(
  File "/usr/lib/python3.8/socket.py", line 787, in create_connection
    for res in getaddrinfo(host, port, 0, SOCK_STREAM):
  File "/usr/lib/python3.8/socket.py", line 918, in getaddrinfo
    for res in _socket.getaddrinfo(host, port, family, type, proto, flags):
socket.gaierror: [Errno -3] Fallo temporal en la resolución del nombre

During handling of the above exception, another exception occurred:

Traceback (most recent call last):
  File "/usr/lib/python3.8/site-packages/libqtile/widget/base.py", line 498, in worker
    text = self.poll()
  File "/usr/lib/python3.8/site-packages/libqtile/widget/generic_poll_text.py", line 85, in poll
    body = self.fetch(self.url, data, headers, self.json, self.xml)
  File "/usr/lib/python3.8/site-packages/libqtile/widget/generic_poll_text.py", line 58, in fetch
    res = urlopen(req)
  File "/usr/lib/python3.8/urllib/request.py", line 222, in urlopen
    return opener.open(url, data, timeout)
  File "/usr/lib/python3.8/urllib/request.py", line 525, in open
    response = self._open(req, data)
  File "/usr/lib/python3.8/urllib/request.py", line 542, in _open
    result = self._call_chain(self.handle_open, protocol, protocol +
  File "/usr/lib/python3.8/urllib/request.py", line 502, in _call_chain
    result = func(*args)
  File "/usr/lib/python3.8/urllib/request.py", line 1393, in https_open
    return self.do_open(http.client.HTTPSConnection, req,
  File "/usr/lib/python3.8/urllib/request.py", line 1353, in do_open
    raise URLError(err)
urllib.error.URLError: <urlopen error [Errno -3] Fallo temporal en la resolución del nombre>[0m

(nitrogen:730): Gtk-WARNING **: 18:52:25.326: Unable to locate theme engine in module_path: "murrine",

(nitrogen:730): Gtk-WARNING **: 18:52:25.326: Unable to locate theme engine in module_path: "murrine",

(nitrogen:730): Gtk-WARNING **: 18:52:25.327: Unable to locate theme engine in module_path: "murrine",

(nitrogen:730): Gtk-WARNING **: 18:52:25.330: Unable to locate theme engine in module_path: "murrine",

(nitrogen:730): Gtk-WARNING **: 18:52:25.330: Unable to locate theme engine in module_path: "murrine",

(nitrogen:730): Gtk-WARNING **: 18:52:25.330: Unable to locate theme engine in module_path: "murrine",

(nitrogen:730): Gtk-WARNING **: 18:52:25.332: Unable to locate theme engine in module_path: "murrine",

(nitrogen:730): Gtk-WARNING **: 18:52:25.332: Unable to locate theme engine in module_path: "murrine",

(nitrogen:730): Gtk-WARNING **: 18:52:25.332: Unable to locate theme engine in module_path: "murrine",

(nitrogen:730): Gtk-WARNING **: 18:52:25.332: Unable to locate theme engine in module_path: "murrine",

(nitrogen:730): Gtk-WARNING **: 18:52:25.333: Unable to locate theme engine in module_path: "murrine",

(nm-applet:732): Gtk-WARNING **: 18:52:25.742: Theme directory 32@2x/devices of theme Vimix-Doder-dark has no size field


(nitrogen:730): Gtk-WARNING **: 18:52:25.795: Unable to locate theme engine in module_path: "murrine",

(nitrogen:730): Gtk-WARNING **: 18:52:25.795: Unable to locate theme engine in module_path: "murrine",

(nitrogen:730): Gtk-WARNING **: 18:52:25.795: Unable to locate theme engine in module_path: "murrine",

(nitrogen:730): Gtk-WARNING **: 18:52:25.797: Unable to locate theme engine in module_path: "murrine",

(nitrogen:730): Gtk-WARNING **: 18:52:25.797: Unable to locate theme engine in module_path: "murrine",

(nitrogen:730): Gtk-WARNING **: 18:52:25.797: Unable to locate theme engine in module_path: "murrine",

(nitrogen:730): Gtk-WARNING **: 18:52:25.799: Unable to locate theme engine in module_path: "murrine",

(nitrogen:730): Gtk-WARNING **: 18:52:25.799: Unable to locate theme engine in module_path: "murrine",

(nitrogen:730): Gtk-WARNING **: 18:52:25.799: Unable to locate theme engine in module_path: "murrine",

(nitrogen:730): Gtk-WARNING **: 18:52:25.799: Unable to locate theme engine in module_path: "murrine",

(nitrogen:730): Gtk-WARNING **: 18:52:25.799: Unable to locate theme engine in module_path: "murrine",

(blueman-applet:733): Gtk-WARNING **: 18:52:26.014: Theme directory 32@2x/devices of theme Vimix-Doder-dark has no size field

blueman-applet 18.52.26 WARNING  PluginManager:147 __load_plugin: Not loading PPPSupport because its conflict has higher priority
blueman-applet 18.52.26 WARNING  PluginManager:147 __load_plugin: Not loading DhcpClient because its conflict has higher priority
blueman-tray version 2.1.3 starting
There is an instance already running
==> ERROR: Cannot fetch updates
[0m[31m2020-06-01 18:52:26,551 [1m[31mlibqtile base.py:worker():L502 [0m problem polling to update widget pacman
Traceback (most recent call last):
  File "/usr/lib/python3.8/site-packages/libqtile/widget/base.py", line 498, in worker
    text = self.poll()
  File "/usr/lib/python3.8/site-packages/libqtile/widget/pacman.py", line 50, in poll
    pacman = self.call_process(['checkupdates'])
  File "/usr/lib/python3.8/site-packages/libqtile/widget/base.py", line 286, in call_process
    output = subprocess.check_output(command, **kwargs)
  File "/usr/lib/python3.8/subprocess.py", line 411, in check_output
    return run(*popenargs, stdout=PIPE, timeout=timeout, check=True,
  File "/usr/lib/python3.8/subprocess.py", line 512, in run
    raise CalledProcessError(retcode, process.args,
subprocess.CalledProcessError: Command '['checkupdates']' returned non-zero exit status 1.[0m

(blueman-tray:924): Gtk-WARNING **: 18:52:26.734: Theme directory 32@2x/devices of theme Vimix-Doder-dark has no size field


(blueman-tray:924): Gdk-CRITICAL **: 18:52:26.759: gdk_window_thaw_toplevel_updates: assertion 'window->update_and_descendants_freeze_count > 0' failed
[0m[31m2020-06-01 18:54:30,400 [1m[31mlibqtile manager.py:process_key_event():L359 [0m KB command error down: No such command[0m
[0m[31m2020-06-01 18:54:30,586 [1m[31mlibqtile manager.py:process_key_event():L359 [0m KB command error down: No such command[0m
[0m[31m2020-06-01 18:54:30,744 [1m[31mlibqtile manager.py:process_key_event():L359 [0m KB command error down: No such command[0m
[0m[31m2020-06-01 18:59:58,492 [1m[31mlibqtile xcore.py:_xpoll():L270 [0m Shutting down due to X connection error XCB_CONN_ERROR (1)
Traceback (most recent call last):
  File "/usr/lib/python3.8/site-packages/xcffib/__init__.py", line 571, in wrapper
    return f(*args)
  File "/usr/lib/python3.8/site-packages/xcffib/__init__.py", line 610, in poll_for_event
    self.invalid()
  File "/usr/lib/python3.8/site-packages/xcffib/__init__.py", line 559, in invalid
    raise ConnectionException(err)
xcffib.ConnectionException: xcb connection errors because of socket, pipe and other stream errors.

During handling of the above exception, another exception occurred:

Traceback (most recent call last):
  File "/usr/lib/python3.8/site-packages/libqtile/backend/x11/xcore.py", line 231, in _xpoll
    event = self.conn.conn.poll_for_event()
  File "/usr/lib/python3.8/site-packages/xcffib/__init__.py", line 573, in wrapper
    self.invalid()
  File "/usr/lib/python3.8/site-packages/xcffib/__init__.py", line 559, in invalid
    raise ConnectionException(err)
xcffib.ConnectionException: xcb connection errors because of socket, pipe and other stream errors.[0m
[0m[31m2020-06-01 18:59:58,493 [1m[31mlibqtile manager.py:get_interesting_pid():L593 [0m Got an exception in getting the window pid
Traceback (most recent call last):
  File "/usr/lib/python3.8/site-packages/xcffib/__init__.py", line 571, in wrapper
    return f(*args)
  File "/usr/lib/python3.8/site-packages/xcffib/__init__.py", line 610, in poll_for_event
    self.invalid()
  File "/usr/lib/python3.8/site-packages/xcffib/__init__.py", line 559, in invalid
    raise ConnectionException(err)
xcffib.ConnectionException: xcb connection errors because of socket, pipe and other stream errors.

During handling of the above exception, another exception occurred:

Traceback (most recent call last):
  File "/usr/lib/python3.8/site-packages/libqtile/backend/x11/xcore.py", line 231, in _xpoll
    event = self.conn.conn.poll_for_event()
  File "/usr/lib/python3.8/site-packages/xcffib/__init__.py", line 573, in wrapper
    self.invalid()
  File "/usr/lib/python3.8/site-packages/xcffib/__init__.py", line 559, in invalid
    raise ConnectionException(err)
xcffib.ConnectionException: xcb connection errors because of socket, pipe and other stream errors.

During handling of the above exception, another exception occurred:

Traceback (most recent call last):
  File "/usr/lib/python3.8/site-packages/libqtile/core/manager.py", line 591, in get_interesting_pid
    return win.window.get_net_wm_pid()
  File "/usr/lib/python3.8/site-packages/libqtile/backend/x11/xcbq.py", line 611, in get_net_wm_pid
    r = self.get_property("_NET_WM_PID", unpack=int)
  File "/usr/lib/python3.8/site-packages/libqtile/backend/x11/xcbq.py", line 704, in get_property
    r = self.conn.conn.core.GetProperty(
  File "/usr/lib/python3.8/site-packages/xcffib/xproto.py", line 2720, in GetProperty
    return self.send_request(20, buf, GetPropertyCookie, is_checked=is_checked)
  File "/usr/lib/python3.8/site-packages/xcffib/__init__.py", line 391, in send_request
    seq = self.conn.send_request(flags, xcb_parts + 2, xcb_req)
  File "/usr/lib/python3.8/site-packages/xcffib/__init__.py", line 569, in wrapper
    self.invalid()
  File "/usr/lib/python3.8/site-packages/xcffib/__init__.py", line 559, in invalid
    raise ConnectionException(err)
xcffib.ConnectionException: xcb connection errors because of socket, pipe and other stream errors.[0m
Exception in callback Qtile.call_later.<locals>.f() at /usr/lib/python3.8/site-packages/libqtile/core/manager.py:888
handle: <TimerHandle when=459.02845618099997 Qtile.call_later.<locals>.f() at /usr/lib/python3.8/site-packages/libqtile/core/manager.py:888>
Traceback (most recent call last):
  File "/usr/lib/python3.8/asyncio/events.py", line 81, in _run
    self._context.run(self._callback, *self._args)
  File "/usr/lib/python3.8/site-packages/libqtile/core/manager.py", line 890, in f
    self.conn.flush()
  File "/usr/lib/python3.8/site-packages/libqtile/backend/x11/xcbq.py", line 955, in flush
    return self.conn.flush()
  File "/usr/lib/python3.8/site-packages/xcffib/__init__.py", line 569, in wrapper
    self.invalid()
  File "/usr/lib/python3.8/site-packages/xcffib/__init__.py", line 559, in invalid
    raise ConnectionException(err)
xcffib.ConnectionException: xcb connection errors because of socket, pipe and other stream errors.
Exception in callback Qtile.call_later.<locals>.f() at /usr/lib/python3.8/site-packages/libqtile/core/manager.py:888
handle: <TimerHandle when=459.051661029 Qtile.call_later.<locals>.f() at /usr/lib/python3.8/site-packages/libqtile/core/manager.py:888>
Traceback (most recent call last):
  File "/usr/lib/python3.8/asyncio/events.py", line 81, in _run
    self._context.run(self._callback, *self._args)
  File "/usr/lib/python3.8/site-packages/libqtile/core/manager.py", line 890, in f
    self.conn.flush()
  File "/usr/lib/python3.8/site-packages/libqtile/backend/x11/xcbq.py", line 955, in flush
    return self.conn.flush()
  File "/usr/lib/python3.8/site-packages/xcffib/__init__.py", line 569, in wrapper
    self.invalid()
  File "/usr/lib/python3.8/site-packages/xcffib/__init__.py", line 559, in invalid
    raise ConnectionException(err)
xcffib.ConnectionException: xcb connection errors because of socket, pipe and other stream errors.
Exception in callback Qtile.call_later.<locals>.f() at /usr/lib/python3.8/site-packages/libqtile/core/manager.py:888
handle: <TimerHandle when=459.052375014 Qtile.call_later.<locals>.f() at /usr/lib/python3.8/site-packages/libqtile/core/manager.py:888>
Traceback (most recent call last):
  File "/usr/lib/python3.8/asyncio/events.py", line 81, in _run
    self._context.run(self._callback, *self._args)
  File "/usr/lib/python3.8/site-packages/libqtile/core/manager.py", line 890, in f
    self.conn.flush()
  File "/usr/lib/python3.8/site-packages/libqtile/backend/x11/xcbq.py", line 955, in flush
    return self.conn.flush()
  File "/usr/lib/python3.8/site-packages/xcffib/__init__.py", line 569, in wrapper
    self.invalid()
  File "/usr/lib/python3.8/site-packages/xcffib/__init__.py", line 559, in invalid
    raise ConnectionException(err)
xcffib.ConnectionException: xcb connection errors because of socket, pipe and other stream errors.
Exception in callback Qtile.call_soon.<locals>.f() at /usr/lib/python3.8/site-packages/libqtile/core/manager.py:874
handle: <Handle Qtile.call_soon.<locals>.f() at /usr/lib/python3.8/site-packages/libqtile/core/manager.py:874>
Traceback (most recent call last):
  File "/usr/lib/python3.8/asyncio/events.py", line 81, in _run
    self._context.run(self._callback, *self._args)
  File "/usr/lib/python3.8/site-packages/libqtile/core/manager.py", line 875, in f
    func(*args)
  File "/usr/lib/python3.8/site-packages/libqtile/bar.py", line 317, in _actual_draw
    i.draw()
  File "/usr/lib/python3.8/site-packages/libqtile/widget/sep.py", line 68, in draw
    self.drawer.draw(offsetx=self.offset, width=self.length)
  File "/usr/lib/python3.8/site-packages/libqtile/drawer.py", line 305, in draw
    self.qtile.conn.conn.core.CopyArea(
  File "/usr/lib/python3.8/site-packages/xcffib/xproto.py", line 3035, in CopyArea
    return self.send_request(62, buf, is_checked=is_checked)
  File "/usr/lib/python3.8/site-packages/xcffib/__init__.py", line 391, in send_request
    seq = self.conn.send_request(flags, xcb_parts + 2, xcb_req)
  File "/usr/lib/python3.8/site-packages/xcffib/__init__.py", line 569, in wrapper
    self.invalid()
  File "/usr/lib/python3.8/site-packages/xcffib/__init__.py", line 559, in invalid
    raise ConnectionException(err)
xcffib.ConnectionException: xcb connection errors because of socket, pipe and other stream errors.
Exception in callback Qtile.call_later.<locals>.f() at /usr/lib/python3.8/site-packages/libqtile/core/manager.py:888
handle: <TimerHandle when=459.59145081741013 Qtile.call_later.<locals>.f() at /usr/lib/python3.8/site-packages/libqtile/core/manager.py:888>
Traceback (most recent call last):
  File "/usr/lib/python3.8/asyncio/events.py", line 81, in _run
    self._context.run(self._callback, *self._args)
  File "/usr/lib/python3.8/site-packages/libqtile/core/manager.py", line 890, in f
    self.conn.flush()
  File "/usr/lib/python3.8/site-packages/libqtile/backend/x11/xcbq.py", line 955, in flush
    return self.conn.flush()
  File "/usr/lib/python3.8/site-packages/xcffib/__init__.py", line 569, in wrapper
    self.invalid()
  File "/usr/lib/python3.8/site-packages/xcffib/__init__.py", line 559, in invalid
    raise ConnectionException(err)
xcffib.ConnectionException: xcb connection errors because of socket, pipe and other stream errors.
[0m[31m2020-06-01 18:59:59,203 [1m[31mlibqtile manager.py:finalize():L303 [0m exception during finalize
Traceback (most recent call last):
  File "/usr/lib/python3.8/site-packages/libqtile/core/manager.py", line 293, in finalize
    widget.finalize()
  File "/usr/lib/python3.8/site-packages/libqtile/widget/base.py", line 208, in finalize
    self.drawer.finalize()
  File "/usr/lib/python3.8/site-packages/libqtile/drawer.py", line 247, in finalize
    self.qtile.conn.conn.core.FreeGC(self.gc)
  File "/usr/lib/python3.8/site-packages/xcffib/xproto.py", line 3027, in FreeGC
    return self.send_request(60, buf, is_checked=is_checked)
  File "/usr/lib/python3.8/site-packages/xcffib/__init__.py", line 391, in send_request
    seq = self.conn.send_request(flags, xcb_parts + 2, xcb_req)
  File "/usr/lib/python3.8/site-packages/xcffib/__init__.py", line 569, in wrapper
    self.invalid()
  File "/usr/lib/python3.8/site-packages/xcffib/__init__.py", line 559, in invalid
    raise ConnectionException(err)
xcffib.ConnectionException: xcb connection errors because of socket, pipe and other stream errors.[0m
[0m[31m2020-06-01 18:59:59,203 [1m[31mlibqtile xcbq.py:disconnect():L950 [0m Failed to disconnect, connection already failed?[0m
[0m[31m2020-06-01 18:59:59,204 [1m[31mlibqtile qtile.py:main():L153 [0m Qtile crashed
Traceback (most recent call last):
  File "/usr/lib/python3.8/site-packages/libqtile/scripts/qtile.py", line 151, in main
    q.loop()
  File "/usr/lib/python3.8/site-packages/libqtile/core/session_manager.py", line 48, in loop
    self.qtile.loop()
  File "/usr/lib/python3.8/site-packages/libqtile/ipc.py", line 234, in __exit__
    self.close()
  File "/usr/lib/python3.8/site-packages/libqtile/ipc.py", line 252, in close
    self.loop.run_until_complete(self.server.wait_closed())
  File "/usr/lib/python3.8/asyncio/base_events.py", line 591, in run_until_complete
    self._check_closed()
  File "/usr/lib/python3.8/asyncio/base_events.py", line 508, in _check_closed
    raise RuntimeError('Event loop is closed')
RuntimeError: Event loop is closed[0m
[0m[33m2020-06-01 19:00:14,693 [1m[33mlibqtile pacman.py:__init__():L38 [0m Pacman is deprecated, please use CheckUpdates[0m
[0m[33m2020-06-01 19:00:14,858 [1m[33mlibqtile pacman.py:__init__():L38 [0m Pacman is deprecated, please use CheckUpdates[0m
[0m[33m2020-06-01 19:00:14,860 [1m[33mlibqtile pacman.py:__init__():L38 [0m Pacman is deprecated, please use CheckUpdates[0m
[ 01/06/20 19:00:15.291 parse_config_libconfig WARN ] Option `no-dock-shadow` is deprecated, and will be removed. Please use the wintype option `shadow` of `dock` instead.
[ 01/06/20 19:00:15.291 parse_config_libconfig WARN ] Option `no-dnd-shadow` is deprecated, and will be removed. Please use the wintype option `shadow` of `dnd` instead.
[ 01/06/20 19:00:15.291 parse_config_libconfig WARN ] Option `menu-opacity` is deprecated, and will be removed.Please use the wintype option `opacity` of `popup_menu` and `dropdown_menu` instead.
[ 01/06/20 19:00:15.291 parse_config_libconfig WARN ] vsync option will take a boolean from now on. "opengl-swc" is interpreted as "true" for compatibility, but this will stop working soon
[ 01/06/20 19:00:15.291 parse_config_libconfig WARN ] glx-swap-method has been deprecated since v6, your setting "exchange" should be replaced by `use-damage = true`.
[ 01/06/20 19:00:15.291 parse_config_libconfig WARN ] "clear-shadow" is removed as an option, and is always enabled now. Consider removing it from your config file
[ 01/06/20 19:00:15.291 session_init WARN ] This compositor has been renamed to "picom", the "compton" binary will not be installed in the future.
[ 01/06/20 19:00:15.391 swopti_init WARN ] --sw-opti is going to be deprecated. If you get real benefits from using this option, please open an issue to let us know.
[0m[31m2020-06-01 19:00:15,383 [1m[31mlibqtile base.py:worker():L502 [0m problem polling to update widget yahooweather
Traceback (most recent call last):
  File "/usr/lib/python3.8/urllib/request.py", line 1350, in do_open
    h.request(req.get_method(), req.selector, req.data, headers,
  File "/usr/lib/python3.8/http/client.py", line 1240, in request
    self._send_request(method, url, body, headers, encode_chunked)
  File "/usr/lib/python3.8/http/client.py", line 1286, in _send_request
    self.endheaders(body, encode_chunked=encode_chunked)
  File "/usr/lib/python3.8/http/client.py", line 1235, in endheaders
    self._send_output(message_body, encode_chunked=encode_chunked)
  File "/usr/lib/python3.8/http/client.py", line 1006, in _send_output
    self.send(msg)
  File "/usr/lib/python3.8/http/client.py", line 946, in send
    self.connect()
  File "/usr/lib/python3.8/http/client.py", line 1402, in connect
    super().connect()
  File "/usr/lib/python3.8/http/client.py", line 917, in connect
    self.sock = self._create_connection(
  File "/usr/lib/python3.8/socket.py", line 787, in create_connection
    for res in getaddrinfo(host, port, 0, SOCK_STREAM):
  File "/usr/lib/python3.8/socket.py", line 918, in getaddrinfo
    for res in _socket.getaddrinfo(host, port, family, type, proto, flags):
socket.gaierror: [Errno -3] Fallo temporal en la resolución del nombre

During handling of the above exception, another exception occurred:

Traceback (most recent call last):
  File "/usr/lib/python3.8/site-packages/libqtile/widget/base.py", line 498, in worker
    text = self.poll()
  File "/usr/lib/python3.8/site-packages/libqtile/widget/generic_poll_text.py", line 85, in poll
    body = self.fetch(self.url, data, headers, self.json, self.xml)
  File "/usr/lib/python3.8/site-packages/libqtile/widget/generic_poll_text.py", line 58, in fetch
    res = urlopen(req)
  File "/usr/lib/python3.8/urllib/request.py", line 222, in urlopen
    return opener.open(url, data, timeout)
  File "/usr/lib/python3.8/urllib/request.py", line 525, in open
    response = self._open(req, data)
  File "/usr/lib/python3.8/urllib/request.py", line 542, in _open
    result = self._call_chain(self.handle_open, protocol, protocol +
  File "/usr/lib/python3.8/urllib/request.py", line 502, in _call_chain
    result = func(*args)
  File "/usr/lib/python3.8/urllib/request.py", line 1393, in https_open
    return self.do_open(http.client.HTTPSConnection, req,
  File "/usr/lib/python3.8/urllib/request.py", line 1353, in do_open
    raise URLError(err)
urllib.error.URLError: <urlopen error [Errno -3] Fallo temporal en la resolución del nombre>[0m

(nitrogen:728): Gtk-WARNING **: 19:00:15.496: Unable to locate theme engine in module_path: "murrine",

(nitrogen:728): Gtk-WARNING **: 19:00:15.497: Unable to locate theme engine in module_path: "murrine",

(nitrogen:728): Gtk-WARNING **: 19:00:15.497: Unable to locate theme engine in module_path: "murrine",

(nitrogen:728): Gtk-WARNING **: 19:00:15.500: Unable to locate theme engine in module_path: "murrine",

(nitrogen:728): Gtk-WARNING **: 19:00:15.500: Unable to locate theme engine in module_path: "murrine",

(nitrogen:728): Gtk-WARNING **: 19:00:15.500: Unable to locate theme engine in module_path: "murrine",

(nitrogen:728): Gtk-WARNING **: 19:00:15.502: Unable to locate theme engine in module_path: "murrine",

(nitrogen:728): Gtk-WARNING **: 19:00:15.503: Unable to locate theme engine in module_path: "murrine",

(nitrogen:728): Gtk-WARNING **: 19:00:15.503: Unable to locate theme engine in module_path: "murrine",

(nitrogen:728): Gtk-WARNING **: 19:00:15.503: Unable to locate theme engine in module_path: "murrine",

(nitrogen:728): Gtk-WARNING **: 19:00:15.505: Unable to locate theme engine in module_path: "murrine",

(nm-applet:730): Gtk-WARNING **: 19:00:15.988: Theme directory 32@2x/devices of theme Vimix-Doder-dark has no size field


(nitrogen:728): Gtk-WARNING **: 19:00:16.053: Unable to locate theme engine in module_path: "murrine",

(nitrogen:728): Gtk-WARNING **: 19:00:16.053: Unable to locate theme engine in module_path: "murrine",

(nitrogen:728): Gtk-WARNING **: 19:00:16.053: Unable to locate theme engine in module_path: "murrine",

(nitrogen:728): Gtk-WARNING **: 19:00:16.055: Unable to locate theme engine in module_path: "murrine",

(nitrogen:728): Gtk-WARNING **: 19:00:16.055: Unable to locate theme engine in module_path: "murrine",

(nitrogen:728): Gtk-WARNING **: 19:00:16.055: Unable to locate theme engine in module_path: "murrine",

(nitrogen:728): Gtk-WARNING **: 19:00:16.056: Unable to locate theme engine in module_path: "murrine",

(nitrogen:728): Gtk-WARNING **: 19:00:16.056: Unable to locate theme engine in module_path: "murrine",

(nitrogen:728): Gtk-WARNING **: 19:00:16.056: Unable to locate theme engine in module_path: "murrine",

(nitrogen:728): Gtk-WARNING **: 19:00:16.057: Unable to locate theme engine in module_path: "murrine",

(nitrogen:728): Gtk-WARNING **: 19:00:16.057: Unable to locate theme engine in module_path: "murrine",

(blueman-applet:731): Gtk-WARNING **: 19:00:16.171: Theme directory 32@2x/devices of theme Vimix-Doder-dark has no size field

blueman-applet 19.00.16 WARNING  PluginManager:147 __load_plugin: Not loading PPPSupport because its conflict has higher priority
blueman-applet 19.00.16 WARNING  PluginManager:147 __load_plugin: Not loading DhcpClient because its conflict has higher priority
blueman-tray version 2.1.3 starting
There is an instance already running

(blueman-tray:910): Gtk-WARNING **: 19:00:16.948: Theme directory 32@2x/devices of theme Vimix-Doder-dark has no size field


(blueman-tray:910): Gdk-CRITICAL **: 19:00:16.980: gdk_window_thaw_toplevel_updates: assertion 'window->update_and_descendants_freeze_count > 0' failed
==> ERROR: Cannot fetch updates
[0m[31m2020-06-01 19:00:17,031 [1m[31mlibqtile base.py:worker():L502 [0m problem polling to update widget pacman
Traceback (most recent call last):
  File "/usr/lib/python3.8/site-packages/libqtile/widget/base.py", line 498, in worker
    text = self.poll()
  File "/usr/lib/python3.8/site-packages/libqtile/widget/pacman.py", line 50, in poll
    pacman = self.call_process(['checkupdates'])
  File "/usr/lib/python3.8/site-packages/libqtile/widget/base.py", line 286, in call_process
    output = subprocess.check_output(command, **kwargs)
  File "/usr/lib/python3.8/subprocess.py", line 411, in check_output
    return run(*popenargs, stdout=PIPE, timeout=timeout, check=True,
  File "/usr/lib/python3.8/subprocess.py", line 512, in run
    raise CalledProcessError(retcode, process.args,
subprocess.CalledProcessError: Command '['checkupdates']' returned non-zero exit status 1.[0m

(deadd-notification-center:732): Gtk-WARNING **: 19:30:41.476: Theme directory 32@2x/devices of theme Vimix-Doder-dark has no size field


(blueman-manager:38328): Gtk-WARNING **: 19:32:08.214: Theme directory 32@2x/devices of theme Vimix-Doder-dark has no size field


(blueman-manager:38328): Gtk-WARNING **: 19:32:08.357: Could not load a pixbuf from icon theme.
This may indicate that pixbuf loaders or the mime database could not be found.
Traceback (most recent call last):
  File "/usr/lib/python3.8/site-packages/blueman/gui/manager/ManagerDeviceList.py", line 495, in _set_device_cell_data
    surface = self.make_device_icon(row["icon_info"], row["paired"], row["trusted"])
  File "/usr/lib/python3.8/site-packages/blueman/gui/manager/ManagerDeviceList.py", line 184, in make_device_icon
    target = icon_info.load_surface(window)
gi.repository.GLib.Error: g-io-error-quark: Error al abrir el archivo /usr/share/icons/Vimix-Doder-dark/scalable/devices/input-mouse.svg: No existe el fichero o el directorio (1)
Traceback (most recent call last):
  File "/usr/lib/python3.8/site-packages/blueman/gui/manager/ManagerDeviceList.py", line 495, in _set_device_cell_data
    surface = self.make_device_icon(row["icon_info"], row["paired"], row["trusted"])
  File "/usr/lib/python3.8/site-packages/blueman/gui/manager/ManagerDeviceList.py", line 184, in make_device_icon
    target = icon_info.load_surface(window)
gi.repository.GLib.Error: g-io-error-quark: Error al abrir el archivo /usr/share/icons/Vimix-Doder-dark/scalable/devices/audio-card.svg: No existe el fichero o el directorio (1)
Traceback (most recent call last):
  File "/usr/lib/python3.8/site-packages/blueman/gui/manager/ManagerDeviceList.py", line 495, in _set_device_cell_data
    surface = self.make_device_icon(row["icon_info"], row["paired"], row["trusted"])
  File "/usr/lib/python3.8/site-packages/blueman/gui/manager/ManagerDeviceList.py", line 184, in make_device_icon
    target = icon_info.load_surface(window)
gi.repository.GLib.Error: g-io-error-quark: Error al abrir el archivo /usr/share/icons/Vimix-Doder-dark/scalable/devices/audio-card.svg: No existe el fichero o el directorio (1)
Traceback (most recent call last):
  File "/usr/lib/python3.8/site-packages/blueman/gui/manager/ManagerDeviceList.py", line 495, in _set_device_cell_data
    surface = self.make_device_icon(row["icon_info"], row["paired"], row["trusted"])
  File "/usr/lib/python3.8/site-packages/blueman/gui/manager/ManagerDeviceList.py", line 184, in make_device_icon
    target = icon_info.load_surface(window)
gi.repository.GLib.Error: g-io-error-quark: Error al abrir el archivo /usr/share/icons/Vimix-Doder-dark/scalable/devices/audio-card.svg: No existe el fichero o el directorio (1)
Traceback (most recent call last):
  File "/usr/lib/python3.8/site-packages/blueman/gui/manager/ManagerDeviceList.py", line 495, in _set_device_cell_data
    surface = self.make_device_icon(row["icon_info"], row["paired"], row["trusted"])
  File "/usr/lib/python3.8/site-packages/blueman/gui/manager/ManagerDeviceList.py", line 184, in make_device_icon
    target = icon_info.load_surface(window)
gi.repository.GLib.Error: g-io-error-quark: Error al abrir el archivo /usr/share/icons/Vimix-Doder-dark/scalable/devices/input-mouse.svg: No existe el fichero o el directorio (1)
Traceback (most recent call last):
  File "/usr/lib/python3.8/site-packages/blueman/gui/manager/ManagerDeviceList.py", line 495, in _set_device_cell_data
    surface = self.make_device_icon(row["icon_info"], row["paired"], row["trusted"])
  File "/usr/lib/python3.8/site-packages/blueman/gui/manager/ManagerDeviceList.py", line 184, in make_device_icon
    target = icon_info.load_surface(window)
gi.repository.GLib.Error: g-io-error-quark: Error al abrir el archivo /usr/share/icons/Vimix-Doder-dark/scalable/devices/input-mouse.svg: No existe el fichero o el directorio (1)
Traceback (most recent call last):
  File "/usr/lib/python3.8/site-packages/blueman/gui/manager/ManagerDeviceList.py", line 495, in _set_device_cell_data
    surface = self.make_device_icon(row["icon_info"], row["paired"], row["trusted"])
  File "/usr/lib/python3.8/site-packages/blueman/gui/manager/ManagerDeviceList.py", line 184, in make_device_icon
    target = icon_info.load_surface(window)
gi.repository.GLib.Error: g-io-error-quark: Error al abrir el archivo /usr/share/icons/Vimix-Doder-dark/scalable/devices/audio-card.svg: No existe el fichero o el directorio (1)
Traceback (most recent call last):
  File "/usr/lib/python3.8/site-packages/blueman/gui/manager/ManagerDeviceList.py", line 495, in _set_device_cell_data
    surface = self.make_device_icon(row["icon_info"], row["paired"], row["trusted"])
  File "/usr/lib/python3.8/site-packages/blueman/gui/manager/ManagerDeviceList.py", line 184, in make_device_icon
    target = icon_info.load_surface(window)
gi.repository.GLib.Error: g-io-error-quark: Error al abrir el archivo /usr/share/icons/Vimix-Doder-dark/scalable/devices/audio-card.svg: No existe el fichero o el directorio (1)
Traceback (most recent call last):
  File "/usr/lib/python3.8/site-packages/blueman/gui/manager/ManagerDeviceList.py", line 495, in _set_device_cell_data
    surface = self.make_device_icon(row["icon_info"], row["paired"], row["trusted"])
  File "/usr/lib/python3.8/site-packages/blueman/gui/manager/ManagerDeviceList.py", line 184, in make_device_icon
    target = icon_info.load_surface(window)
gi.repository.GLib.Error: g-io-error-quark: Error al abrir el archivo /usr/share/icons/Vimix-Doder-dark/scalable/devices/input-mouse.svg: No existe el fichero o el directorio (1)
Traceback (most recent call last):
  File "/usr/lib/python3.8/site-packages/blueman/gui/manager/ManagerDeviceList.py", line 495, in _set_device_cell_data
    surface = self.make_device_icon(row["icon_info"], row["paired"], row["trusted"])
  File "/usr/lib/python3.8/site-packages/blueman/gui/manager/ManagerDeviceList.py", line 184, in make_device_icon
    target = icon_info.load_surface(window)
gi.repository.GLib.Error: g-io-error-quark: Error al abrir el archivo /usr/share/icons/Vimix-Doder-dark/scalable/devices/input-mouse.svg: No existe el fichero o el directorio (1)
Traceback (most recent call last):
  File "/usr/lib/python3.8/site-packages/blueman/gui/manager/ManagerDeviceList.py", line 495, in _set_device_cell_data
    surface = self.make_device_icon(row["icon_info"], row["paired"], row["trusted"])
  File "/usr/lib/python3.8/site-packages/blueman/gui/manager/ManagerDeviceList.py", line 184, in make_device_icon
    target = icon_info.load_surface(window)
gi.repository.GLib.Error: g-io-error-quark: Error al abrir el archivo /usr/share/icons/Vimix-Doder-dark/scalable/devices/audio-card.svg: No existe el fichero o el directorio (1)
Traceback (most recent call last):
  File "/usr/lib/python3.8/site-packages/blueman/gui/manager/ManagerDeviceList.py", line 495, in _set_device_cell_data
    surface = self.make_device_icon(row["icon_info"], row["paired"], row["trusted"])
  File "/usr/lib/python3.8/site-packages/blueman/gui/manager/ManagerDeviceList.py", line 184, in make_device_icon
    target = icon_info.load_surface(window)
gi.repository.GLib.Error: g-io-error-quark: Error al abrir el archivo /usr/share/icons/Vimix-Doder-dark/scalable/devices/audio-card.svg: No existe el fichero o el directorio (1)
Traceback (most recent call last):
  File "/usr/lib/python3.8/site-packages/blueman/gui/manager/ManagerDeviceList.py", line 495, in _set_device_cell_data
    surface = self.make_device_icon(row["icon_info"], row["paired"], row["trusted"])
  File "/usr/lib/python3.8/site-packages/blueman/gui/manager/ManagerDeviceList.py", line 184, in make_device_icon
    target = icon_info.load_surface(window)
gi.repository.GLib.Error: g-io-error-quark: Error al abrir el archivo /usr/share/icons/Vimix-Doder-dark/scalable/devices/input-mouse.svg: No existe el fichero o el directorio (1)
Traceback (most recent call last):
  File "/usr/lib/python3.8/site-packages/blueman/gui/manager/ManagerDeviceList.py", line 495, in _set_device_cell_data
    surface = self.make_device_icon(row["icon_info"], row["paired"], row["trusted"])
  File "/usr/lib/python3.8/site-packages/blueman/gui/manager/ManagerDeviceList.py", line 184, in make_device_icon
    target = icon_info.load_surface(window)
gi.repository.GLib.Error: g-io-error-quark: Error al abrir el archivo /usr/share/icons/Vimix-Doder-dark/scalable/devices/input-mouse.svg: No existe el fichero o el directorio (1)
Traceback (most recent call last):
  File "/usr/lib/python3.8/site-packages/blueman/gui/manager/ManagerDeviceList.py", line 495, in _set_device_cell_data
    surface = self.make_device_icon(row["icon_info"], row["paired"], row["trusted"])
  File "/usr/lib/python3.8/site-packages/blueman/gui/manager/ManagerDeviceList.py", line 184, in make_device_icon
    target = icon_info.load_surface(window)
gi.repository.GLib.Error: g-io-error-quark: Error al abrir el archivo /usr/share/icons/Vimix-Doder-dark/scalable/devices/audio-card.svg: No existe el fichero o el directorio (1)
Traceback (most recent call last):
  File "/usr/lib/python3.8/site-packages/blueman/gui/manager/ManagerDeviceList.py", line 495, in _set_device_cell_data
    surface = self.make_device_icon(row["icon_info"], row["paired"], row["trusted"])
  File "/usr/lib/python3.8/site-packages/blueman/gui/manager/ManagerDeviceList.py", line 184, in make_device_icon
    target = icon_info.load_surface(window)
gi.repository.GLib.Error: g-io-error-quark: Error al abrir el archivo /usr/share/icons/Vimix-Doder-dark/scalable/devices/audio-card.svg: No existe el fichero o el directorio (1)
Traceback (most recent call last):
  File "/usr/lib/python3.8/site-packages/blueman/gui/manager/ManagerDeviceList.py", line 495, in _set_device_cell_data
    surface = self.make_device_icon(row["icon_info"], row["paired"], row["trusted"])
  File "/usr/lib/python3.8/site-packages/blueman/gui/manager/ManagerDeviceList.py", line 184, in make_device_icon
    target = icon_info.load_surface(window)
gi.repository.GLib.Error: g-io-error-quark: Error al abrir el archivo /usr/share/icons/Vimix-Doder-dark/scalable/devices/input-mouse.svg: No existe el fichero o el directorio (1)
Traceback (most recent call last):
  File "/usr/lib/python3.8/site-packages/blueman/gui/manager/ManagerDeviceList.py", line 495, in _set_device_cell_data
    surface = self.make_device_icon(row["icon_info"], row["paired"], row["trusted"])
  File "/usr/lib/python3.8/site-packages/blueman/gui/manager/ManagerDeviceList.py", line 184, in make_device_icon
    target = icon_info.load_surface(window)
gi.repository.GLib.Error: g-io-error-quark: Error al abrir el archivo /usr/share/icons/Vimix-Doder-dark/scalable/devices/input-mouse.svg: No existe el fichero o el directorio (1)
Traceback (most recent call last):
  File "/usr/lib/python3.8/site-packages/blueman/gui/manager/ManagerDeviceList.py", line 495, in _set_device_cell_data
    surface = self.make_device_icon(row["icon_info"], row["paired"], row["trusted"])
  File "/usr/lib/python3.8/site-packages/blueman/gui/manager/ManagerDeviceList.py", line 184, in make_device_icon
    target = icon_info.load_surface(window)
gi.repository.GLib.Error: g-io-error-quark: Error al abrir el archivo /usr/share/icons/Vimix-Doder-dark/scalable/devices/audio-card.svg: No existe el fichero o el directorio (1)
Traceback (most recent call last):
  File "/usr/lib/python3.8/site-packages/blueman/gui/manager/ManagerDeviceList.py", line 495, in _set_device_cell_data
    surface = self.make_device_icon(row["icon_info"], row["paired"], row["trusted"])
  File "/usr/lib/python3.8/site-packages/blueman/gui/manager/ManagerDeviceList.py", line 184, in make_device_icon
    target = icon_info.load_surface(window)
gi.repository.GLib.Error: g-io-error-quark: Error al abrir el archivo /usr/share/icons/Vimix-Doder-dark/scalable/devices/audio-card.svg: No existe el fichero o el directorio (1)
Traceback (most recent call last):
  File "/usr/lib/python3.8/site-packages/blueman/gui/manager/ManagerDeviceList.py", line 495, in _set_device_cell_data
    surface = self.make_device_icon(row["icon_info"], row["paired"], row["trusted"])
  File "/usr/lib/python3.8/site-packages/blueman/gui/manager/ManagerDeviceList.py", line 184, in make_device_icon
    target = icon_info.load_surface(window)
gi.repository.GLib.Error: g-io-error-quark: Error al abrir el archivo /usr/share/icons/Vimix-Doder-dark/scalable/devices/input-mouse.svg: No existe el fichero o el directorio (1)
Traceback (most recent call last):
  File "/usr/lib/python3.8/site-packages/blueman/gui/manager/ManagerDeviceList.py", line 495, in _set_device_cell_data
    surface = self.make_device_icon(row["icon_info"], row["paired"], row["trusted"])
  File "/usr/lib/python3.8/site-packages/blueman/gui/manager/ManagerDeviceList.py", line 184, in make_device_icon
    target = icon_info.load_surface(window)
gi.repository.GLib.Error: g-io-error-quark: Error al abrir el archivo /usr/share/icons/Vimix-Doder-dark/scalable/devices/input-mouse.svg: No existe el fichero o el directorio (1)
Traceback (most recent call last):
  File "/usr/lib/python3.8/site-packages/blueman/gui/manager/ManagerDeviceList.py", line 495, in _set_device_cell_data
    surface = self.make_device_icon(row["icon_info"], row["paired"], row["trusted"])
  File "/usr/lib/python3.8/site-packages/blueman/gui/manager/ManagerDeviceList.py", line 184, in make_device_icon
    target = icon_info.load_surface(window)
gi.repository.GLib.Error: g-io-error-quark: Error al abrir el archivo /usr/share/icons/Vimix-Doder-dark/scalable/devices/audio-card.svg: No existe el fichero o el directorio (1)
Traceback (most recent call last):
  File "/usr/lib/python3.8/site-packages/blueman/gui/manager/ManagerDeviceList.py", line 495, in _set_device_cell_data
    surface = self.make_device_icon(row["icon_info"], row["paired"], row["trusted"])
  File "/usr/lib/python3.8/site-packages/blueman/gui/manager/ManagerDeviceList.py", line 184, in make_device_icon
    target = icon_info.load_surface(window)
gi.repository.GLib.Error: g-io-error-quark: Error al abrir el archivo /usr/share/icons/Vimix-Doder-dark/scalable/devices/audio-card.svg: No existe el fichero o el directorio (1)
Traceback (most recent call last):
  File "/usr/lib/python3.8/site-packages/blueman/gui/manager/ManagerDeviceList.py", line 495, in _set_device_cell_data
    surface = self.make_device_icon(row["icon_info"], row["paired"], row["trusted"])
  File "/usr/lib/python3.8/site-packages/blueman/gui/manager/ManagerDeviceList.py", line 184, in make_device_icon
    target = icon_info.load_surface(window)
gi.repository.GLib.Error: g-io-error-quark: Error al abrir el archivo /usr/share/icons/Vimix-Doder-dark/scalable/devices/input-mouse.svg: No existe el fichero o el directorio (1)
Traceback (most recent call last):
  File "/usr/lib/python3.8/site-packages/blueman/gui/manager/ManagerDeviceList.py", line 495, in _set_device_cell_data
    surface = self.make_device_icon(row["icon_info"], row["paired"], row["trusted"])
  File "/usr/lib/python3.8/site-packages/blueman/gui/manager/ManagerDeviceList.py", line 184, in make_device_icon
    target = icon_info.load_surface(window)
gi.repository.GLib.Error: g-io-error-quark: Error al abrir el archivo /usr/share/icons/Vimix-Doder-dark/scalable/devices/input-mouse.svg: No existe el fichero o el directorio (1)
Traceback (most recent call last):
  File "/usr/lib/python3.8/site-packages/blueman/gui/manager/ManagerDeviceList.py", line 495, in _set_device_cell_data
    surface = self.make_device_icon(row["icon_info"], row["paired"], row["trusted"])
  File "/usr/lib/python3.8/site-packages/blueman/gui/manager/ManagerDeviceList.py", line 184, in make_device_icon
    target = icon_info.load_surface(window)
gi.repository.GLib.Error: g-io-error-quark: Error al abrir el archivo /usr/share/icons/Vimix-Doder-dark/scalable/devices/audio-card.svg: No existe el fichero o el directorio (1)
Traceback (most recent call last):
  File "/usr/lib/python3.8/site-packages/blueman/gui/manager/ManagerDeviceList.py", line 495, in _set_device_cell_data
    surface = self.make_device_icon(row["icon_info"], row["paired"], row["trusted"])
  File "/usr/lib/python3.8/site-packages/blueman/gui/manager/ManagerDeviceList.py", line 184, in make_device_icon
    target = icon_info.load_surface(window)
gi.repository.GLib.Error: g-io-error-quark: Error al abrir el archivo /usr/share/icons/Vimix-Doder-dark/scalable/devices/audio-card.svg: No existe el fichero o el directorio (1)
Traceback (most recent call last):
  File "/usr/lib/python3.8/site-packages/blueman/gui/manager/ManagerDeviceList.py", line 495, in _set_device_cell_data
    surface = self.make_device_icon(row["icon_info"], row["paired"], row["trusted"])
  File "/usr/lib/python3.8/site-packages/blueman/gui/manager/ManagerDeviceList.py", line 184, in make_device_icon
    target = icon_info.load_surface(window)
gi.repository.GLib.Error: g-io-error-quark: Error al abrir el archivo /usr/share/icons/Vimix-Doder-dark/scalable/devices/input-mouse.svg: No existe el fichero o el directorio (1)
Traceback (most recent call last):
  File "/usr/lib/python3.8/site-packages/blueman/gui/manager/ManagerDeviceList.py", line 495, in _set_device_cell_data
    surface = self.make_device_icon(row["icon_info"], row["paired"], row["trusted"])
  File "/usr/lib/python3.8/site-packages/blueman/gui/manager/ManagerDeviceList.py", line 184, in make_device_icon
    target = icon_info.load_surface(window)
gi.repository.GLib.Error: g-io-error-quark: Error al abrir el archivo /usr/share/icons/Vimix-Doder-dark/scalable/devices/input-mouse.svg: No existe el fichero o el directorio (1)
Traceback (most recent call last):
  File "/usr/lib/python3.8/site-packages/blueman/gui/manager/ManagerDeviceList.py", line 495, in _set_device_cell_data
    surface = self.make_device_icon(row["icon_info"], row["paired"], row["trusted"])
  File "/usr/lib/python3.8/site-packages/blueman/gui/manager/ManagerDeviceList.py", line 184, in make_device_icon
    target = icon_info.load_surface(window)
gi.repository.GLib.Error: g-io-error-quark: Error al abrir el archivo /usr/share/icons/Vimix-Doder-dark/scalable/devices/audio-card.svg: No existe el fichero o el directorio (1)
Traceback (most recent call last):
  File "/usr/lib/python3.8/site-packages/blueman/gui/manager/ManagerDeviceList.py", line 495, in _set_device_cell_data
    surface = self.make_device_icon(row["icon_info"], row["paired"], row["trusted"])
  File "/usr/lib/python3.8/site-packages/blueman/gui/manager/ManagerDeviceList.py", line 184, in make_device_icon
    target = icon_info.load_surface(window)
gi.repository.GLib.Error: g-io-error-quark: Error al abrir el archivo /usr/share/icons/Vimix-Doder-dark/scalable/devices/audio-card.svg: No existe el fichero o el directorio (1)
Traceback (most recent call last):
  File "/usr/lib/python3.8/site-packages/blueman/gui/manager/ManagerDeviceList.py", line 495, in _set_device_cell_data
    surface = self.make_device_icon(row["icon_info"], row["paired"], row["trusted"])
  File "/usr/lib/python3.8/site-packages/blueman/gui/manager/ManagerDeviceList.py", line 184, in make_device_icon
    target = icon_info.load_surface(window)
gi.repository.GLib.Error: g-io-error-quark: Error al abrir el archivo /usr/share/icons/Vimix-Doder-dark/scalable/devices/input-mouse.svg: No existe el fichero o el directorio (1)
Traceback (most recent call last):
  File "/usr/lib/python3.8/site-packages/blueman/gui/manager/ManagerDeviceList.py", line 495, in _set_device_cell_data
    surface = self.make_device_icon(row["icon_info"], row["paired"], row["trusted"])
  File "/usr/lib/python3.8/site-packages/blueman/gui/manager/ManagerDeviceList.py", line 184, in make_device_icon
    target = icon_info.load_surface(window)
gi.repository.GLib.Error: g-io-error-quark: Error al abrir el archivo /usr/share/icons/Vimix-Doder-dark/scalable/devices/input-mouse.svg: No existe el fichero o el directorio (1)
Traceback (most recent call last):
  File "/usr/lib/python3.8/site-packages/blueman/gui/manager/ManagerDeviceList.py", line 495, in _set_device_cell_data
    surface = self.make_device_icon(row["icon_info"], row["paired"], row["trusted"])
  File "/usr/lib/python3.8/site-packages/blueman/gui/manager/ManagerDeviceList.py", line 184, in make_device_icon
    target = icon_info.load_surface(window)
gi.repository.GLib.Error: g-io-error-quark: Error al abrir el archivo /usr/share/icons/Vimix-Doder-dark/scalable/devices/audio-card.svg: No existe el fichero o el directorio (1)
Traceback (most recent call last):
  File "/usr/lib/python3.8/site-packages/blueman/gui/manager/ManagerDeviceList.py", line 495, in _set_device_cell_data
    surface = self.make_device_icon(row["icon_info"], row["paired"], row["trusted"])
  File "/usr/lib/python3.8/site-packages/blueman/gui/manager/ManagerDeviceList.py", line 184, in make_device_icon
    target = icon_info.load_surface(window)
gi.repository.GLib.Error: g-io-error-quark: Error al abrir el archivo /usr/share/icons/Vimix-Doder-dark/scalable/devices/audio-card.svg: No existe el fichero o el directorio (1)
Traceback (most recent call last):
  File "/usr/lib/python3.8/site-packages/blueman/gui/manager/ManagerDeviceList.py", line 495, in _set_device_cell_data
    surface = self.make_device_icon(row["icon_info"], row["paired"], row["trusted"])
  File "/usr/lib/python3.8/site-packages/blueman/gui/manager/ManagerDeviceList.py", line 184, in make_device_icon
    target = icon_info.load_surface(window)
gi.repository.GLib.Error: g-io-error-quark: Error al abrir el archivo /usr/share/icons/Vimix-Doder-dark/scalable/devices/input-mouse.svg: No existe el fichero o el directorio (1)
Traceback (most recent call last):
  File "/usr/lib/python3.8/site-packages/blueman/gui/manager/ManagerDeviceList.py", line 495, in _set_device_cell_data
    surface = self.make_device_icon(row["icon_info"], row["paired"], row["trusted"])
  File "/usr/lib/python3.8/site-packages/blueman/gui/manager/ManagerDeviceList.py", line 184, in make_device_icon
    target = icon_info.load_surface(window)
gi.repository.GLib.Error: g-io-error-quark: Error al abrir el archivo /usr/share/icons/Vimix-Doder-dark/scalable/devices/input-mouse.svg: No existe el fichero o el directorio (1)
Traceback (most recent call last):
  File "/usr/lib/python3.8/site-packages/blueman/gui/manager/ManagerDeviceList.py", line 495, in _set_device_cell_data
    surface = self.make_device_icon(row["icon_info"], row["paired"], row["trusted"])
  File "/usr/lib/python3.8/site-packages/blueman/gui/manager/ManagerDeviceList.py", line 184, in make_device_icon
    target = icon_info.load_surface(window)
gi.repository.GLib.Error: g-io-error-quark: Error al abrir el archivo /usr/share/icons/Vimix-Doder-dark/scalable/devices/audio-card.svg: No existe el fichero o el directorio (1)
Traceback (most recent call last):
  File "/usr/lib/python3.8/site-packages/blueman/gui/manager/ManagerDeviceList.py", line 495, in _set_device_cell_data
    surface = self.make_device_icon(row["icon_info"], row["paired"], row["trusted"])
  File "/usr/lib/python3.8/site-packages/blueman/gui/manager/ManagerDeviceList.py", line 184, in make_device_icon
    target = icon_info.load_surface(window)
gi.repository.GLib.Error: g-io-error-quark: Error al abrir el archivo /usr/share/icons/Vimix-Doder-dark/scalable/devices/audio-card.svg: No existe el fichero o el directorio (1)
Traceback (most recent call last):
  File "/usr/lib/python3.8/site-packages/blueman/gui/manager/ManagerDeviceList.py", line 495, in _set_device_cell_data
    surface = self.make_device_icon(row["icon_info"], row["paired"], row["trusted"])
  File "/usr/lib/python3.8/site-packages/blueman/gui/manager/ManagerDeviceList.py", line 184, in make_device_icon
    target = icon_info.load_surface(window)
gi.repository.GLib.Error: g-io-error-quark: Error al abrir el archivo /usr/share/icons/Vimix-Doder-dark/scalable/devices/input-mouse.svg: No existe el fichero o el directorio (1)
Traceback (most recent call last):
  File "/usr/lib/python3.8/site-packages/blueman/gui/manager/ManagerDeviceList.py", line 495, in _set_device_cell_data
    surface = self.make_device_icon(row["icon_info"], row["paired"], row["trusted"])
  File "/usr/lib/python3.8/site-packages/blueman/gui/manager/ManagerDeviceList.py", line 184, in make_device_icon
    target = icon_info.load_surface(window)
gi.repository.GLib.Error: g-io-error-quark: Error al abrir el archivo /usr/share/icons/Vimix-Doder-dark/scalable/devices/input-mouse.svg: No existe el fichero o el directorio (1)
Traceback (most recent call last):
  File "/usr/lib/python3.8/site-packages/blueman/gui/manager/ManagerDeviceList.py", line 495, in _set_device_cell_data
    surface = self.make_device_icon(row["icon_info"], row["paired"], row["trusted"])
  File "/usr/lib/python3.8/site-packages/blueman/gui/manager/ManagerDeviceList.py", line 184, in make_device_icon
    target = icon_info.load_surface(window)
gi.repository.GLib.Error: g-io-error-quark: Error al abrir el archivo /usr/share/icons/Vimix-Doder-dark/scalable/devices/audio-card.svg: No existe el fichero o el directorio (1)
Traceback (most recent call last):
  File "/usr/lib/python3.8/site-packages/blueman/gui/manager/ManagerDeviceList.py", line 495, in _set_device_cell_data
    surface = self.make_device_icon(row["icon_info"], row["paired"], row["trusted"])
  File "/usr/lib/python3.8/site-packages/blueman/gui/manager/ManagerDeviceList.py", line 184, in make_device_icon
    target = icon_info.load_surface(window)
gi.repository.GLib.Error: g-io-error-quark: Error al abrir el archivo /usr/share/icons/Vimix-Doder-dark/scalable/devices/audio-card.svg: No existe el fichero o el directorio (1)
Traceback (most recent call last):
  File "/usr/lib/python3.8/site-packages/blueman/gui/manager/ManagerDeviceList.py", line 495, in _set_device_cell_data
    surface = self.make_device_icon(row["icon_info"], row["paired"], row["trusted"])
  File "/usr/lib/python3.8/site-packages/blueman/gui/manager/ManagerDeviceList.py", line 184, in make_device_icon
    target = icon_info.load_surface(window)
gi.repository.GLib.Error: g-io-error-quark: Error al abrir el archivo /usr/share/icons/Vimix-Doder-dark/scalable/devices/input-mouse.svg: No existe el fichero o el directorio (1)
Traceback (most recent call last):
  File "/usr/lib/python3.8/site-packages/blueman/gui/manager/ManagerDeviceList.py", line 495, in _set_device_cell_data
    surface = self.make_device_icon(row["icon_info"], row["paired"], row["trusted"])
  File "/usr/lib/python3.8/site-packages/blueman/gui/manager/ManagerDeviceList.py", line 184, in make_device_icon
    target = icon_info.load_surface(window)
gi.repository.GLib.Error: g-io-error-quark: Error al abrir el archivo /usr/share/icons/Vimix-Doder-dark/scalable/devices/input-mouse.svg: No existe el fichero o el directorio (1)
Traceback (most recent call last):
  File "/usr/lib/python3.8/site-packages/blueman/gui/manager/ManagerDeviceList.py", line 495, in _set_device_cell_data
    surface = self.make_device_icon(row["icon_info"], row["paired"], row["trusted"])
  File "/usr/lib/python3.8/site-packages/blueman/gui/manager/ManagerDeviceList.py", line 184, in make_device_icon
    target = icon_info.load_surface(window)
gi.repository.GLib.Error: g-io-error-quark: Error al abrir el archivo /usr/share/icons/Vimix-Doder-dark/scalable/devices/audio-card.svg: No existe el fichero o el directorio (1)
Traceback (most recent call last):
  File "/usr/lib/python3.8/site-packages/blueman/gui/manager/ManagerDeviceList.py", line 495, in _set_device_cell_data
    surface = self.make_device_icon(row["icon_info"], row["paired"], row["trusted"])
  File "/usr/lib/python3.8/site-packages/blueman/gui/manager/ManagerDeviceList.py", line 184, in make_device_icon
    target = icon_info.load_surface(window)
gi.repository.GLib.Error: g-io-error-quark: Error al abrir el archivo /usr/share/icons/Vimix-Doder-dark/scalable/devices/audio-card.svg: No existe el fichero o el directorio (1)
Traceback (most recent call last):
  File "/usr/lib/python3.8/site-packages/blueman/gui/manager/ManagerDeviceList.py", line 495, in _set_device_cell_data
    surface = self.make_device_icon(row["icon_info"], row["paired"], row["trusted"])
  File "/usr/lib/python3.8/site-packages/blueman/gui/manager/ManagerDeviceList.py", line 184, in make_device_icon
    target = icon_info.load_surface(window)
gi.repository.GLib.Error: g-io-error-quark: Error al abrir el archivo /usr/share/icons/Vimix-Doder-dark/scalable/devices/input-mouse.svg: No existe el fichero o el directorio (1)
Traceback (most recent call last):
  File "/usr/lib/python3.8/site-packages/blueman/gui/manager/ManagerDeviceList.py", line 495, in _set_device_cell_data
    surface = self.make_device_icon(row["icon_info"], row["paired"], row["trusted"])
  File "/usr/lib/python3.8/site-packages/blueman/gui/manager/ManagerDeviceList.py", line 184, in make_device_icon
    target = icon_info.load_surface(window)
gi.repository.GLib.Error: g-io-error-quark: Error al abrir el archivo /usr/share/icons/Vimix-Doder-dark/scalable/devices/input-mouse.svg: No existe el fichero o el directorio (1)
Traceback (most recent call last):
  File "/usr/lib/python3.8/site-packages/blueman/gui/manager/ManagerDeviceList.py", line 495, in _set_device_cell_data
    surface = self.make_device_icon(row["icon_info"], row["paired"], row["trusted"])
  File "/usr/lib/python3.8/site-packages/blueman/gui/manager/ManagerDeviceList.py", line 184, in make_device_icon
    target = icon_info.load_surface(window)
gi.repository.GLib.Error: g-io-error-quark: Error al abrir el archivo /usr/share/icons/Vimix-Doder-dark/scalable/devices/audio-card.svg: No existe el fichero o el directorio (1)
Traceback (most recent call last):
  File "/usr/lib/python3.8/site-packages/blueman/gui/manager/ManagerDeviceList.py", line 495, in _set_device_cell_data
    surface = self.make_device_icon(row["icon_info"], row["paired"], row["trusted"])
  File "/usr/lib/python3.8/site-packages/blueman/gui/manager/ManagerDeviceList.py", line 184, in make_device_icon
    target = icon_info.load_surface(window)
gi.repository.GLib.Error: g-io-error-quark: Error al abrir el archivo /usr/share/icons/Vimix-Doder-dark/scalable/devices/audio-card.svg: No existe el fichero o el directorio (1)
Traceback (most recent call last):
  File "/usr/lib/python3.8/site-packages/blueman/gui/manager/ManagerDeviceList.py", line 495, in _set_device_cell_data
    surface = self.make_device_icon(row["icon_info"], row["paired"], row["trusted"])
  File "/usr/lib/python3.8/site-packages/blueman/gui/manager/ManagerDeviceList.py", line 184, in make_device_icon
    target = icon_info.load_surface(window)
gi.repository.GLib.Error: g-io-error-quark: Error al abrir el archivo /usr/share/icons/Vimix-Doder-dark/scalable/devices/input-mouse.svg: No existe el fichero o el directorio (1)
Traceback (most recent call last):
  File "/usr/lib/python3.8/site-packages/blueman/gui/manager/ManagerDeviceList.py", line 495, in _set_device_cell_data
    surface = self.make_device_icon(row["icon_info"], row["paired"], row["trusted"])
  File "/usr/lib/python3.8/site-packages/blueman/gui/manager/ManagerDeviceList.py", line 184, in make_device_icon
    target = icon_info.load_surface(window)
gi.repository.GLib.Error: g-io-error-quark: Error al abrir el archivo /usr/share/icons/Vimix-Doder-dark/scalable/devices/input-mouse.svg: No existe el fichero o el directorio (1)
Traceback (most recent call last):
  File "/usr/lib/python3.8/site-packages/blueman/gui/manager/ManagerDeviceList.py", line 495, in _set_device_cell_data
    surface = self.make_device_icon(row["icon_info"], row["paired"], row["trusted"])
  File "/usr/lib/python3.8/site-packages/blueman/gui/manager/ManagerDeviceList.py", line 184, in make_device_icon
    target = icon_info.load_surface(window)
gi.repository.GLib.Error: g-io-error-quark: Error al abrir el archivo /usr/share/icons/Vimix-Doder-dark/scalable/devices/audio-card.svg: No existe el fichero o el directorio (1)
Traceback (most recent call last):
  File "/usr/lib/python3.8/site-packages/blueman/gui/manager/ManagerDeviceList.py", line 495, in _set_device_cell_data
    surface = self.make_device_icon(row["icon_info"], row["paired"], row["trusted"])
  File "/usr/lib/python3.8/site-packages/blueman/gui/manager/ManagerDeviceList.py", line 184, in make_device_icon
    target = icon_info.load_surface(window)
gi.repository.GLib.Error: g-io-error-quark: Error al abrir el archivo /usr/share/icons/Vimix-Doder-dark/scalable/devices/input-mouse.svg: No existe el fichero o el directorio (1)
Traceback (most recent call last):
  File "/usr/lib/python3.8/site-packages/blueman/gui/manager/ManagerDeviceList.py", line 495, in _set_device_cell_data
    surface = self.make_device_icon(row["icon_info"], row["paired"], row["trusted"])
  File "/usr/lib/python3.8/site-packages/blueman/gui/manager/ManagerDeviceList.py", line 184, in make_device_icon
    target = icon_info.load_surface(window)
gi.repository.GLib.Error: g-io-error-quark: Error al abrir el archivo /usr/share/icons/Vimix-Doder-dark/scalable/devices/input-mouse.svg: No existe el fichero o el directorio (1)
Traceback (most recent call last):
  File "/usr/lib/python3.8/site-packages/blueman/gui/manager/ManagerDeviceList.py", line 495, in _set_device_cell_data
    surface = self.make_device_icon(row["icon_info"], row["paired"], row["trusted"])
  File "/usr/lib/python3.8/site-packages/blueman/gui/manager/ManagerDeviceList.py", line 184, in make_device_icon
    target = icon_info.load_surface(window)
gi.repository.GLib.Error: g-io-error-quark: Error al abrir el archivo /usr/share/icons/Vimix-Doder-dark/scalable/devices/audio-card.svg: No existe el fichero o el directorio (1)
Traceback (most recent call last):
  File "/usr/lib/python3.8/site-packages/blueman/gui/manager/ManagerDeviceList.py", line 495, in _set_device_cell_data
    surface = self.make_device_icon(row["icon_info"], row["paired"], row["trusted"])
  File "/usr/lib/python3.8/site-packages/blueman/gui/manager/ManagerDeviceList.py", line 184, in make_device_icon
    target = icon_info.load_surface(window)
gi.repository.GLib.Error: g-io-error-quark: Error al abrir el archivo /usr/share/icons/Vimix-Doder-dark/scalable/devices/audio-card.svg: No existe el fichero o el directorio (1)
Traceback (most recent call last):
  File "/usr/lib/python3.8/site-packages/blueman/gui/manager/ManagerDeviceList.py", line 495, in _set_device_cell_data
    surface = self.make_device_icon(row["icon_info"], row["paired"], row["trusted"])
  File "/usr/lib/python3.8/site-packages/blueman/gui/manager/ManagerDeviceList.py", line 184, in make_device_icon
    target = icon_info.load_surface(window)
gi.repository.GLib.Error: g-io-error-quark: Error al abrir el archivo /usr/share/icons/Vimix-Doder-dark/scalable/devices/input-mouse.svg: No existe el fichero o el directorio (1)
Traceback (most recent call last):
  File "/usr/lib/python3.8/site-packages/blueman/gui/manager/ManagerDeviceList.py", line 495, in _set_device_cell_data
    surface = self.make_device_icon(row["icon_info"], row["paired"], row["trusted"])
  File "/usr/lib/python3.8/site-packages/blueman/gui/manager/ManagerDeviceList.py", line 184, in make_device_icon
    target = icon_info.load_surface(window)
gi.repository.GLib.Error: g-io-error-quark: Error al abrir el archivo /usr/share/icons/Vimix-Doder-dark/scalable/devices/input-mouse.svg: No existe el fichero o el directorio (1)
Traceback (most recent call last):
  File "/usr/lib/python3.8/site-packages/blueman/gui/manager/ManagerDeviceList.py", line 495, in _set_device_cell_data
    surface = self.make_device_icon(row["icon_info"], row["paired"], row["trusted"])
  File "/usr/lib/python3.8/site-packages/blueman/gui/manager/ManagerDeviceList.py", line 184, in make_device_icon
    target = icon_info.load_surface(window)
gi.repository.GLib.Error: g-io-error-quark: Error al abrir el archivo /usr/share/icons/Vimix-Doder-dark/scalable/devices/audio-card.svg: No existe el fichero o el directorio (1)
Traceback (most recent call last):
  File "/usr/lib/python3.8/site-packages/blueman/gui/manager/ManagerDeviceList.py", line 495, in _set_device_cell_data
    surface = self.make_device_icon(row["icon_info"], row["paired"], row["trusted"])
  File "/usr/lib/python3.8/site-packages/blueman/gui/manager/ManagerDeviceList.py", line 184, in make_device_icon
    target = icon_info.load_surface(window)
gi.repository.GLib.Error: g-io-error-quark: Error al abrir el archivo /usr/share/icons/Vimix-Doder-dark/scalable/devices/audio-card.svg: No existe el fichero o el directorio (1)
Traceback (most recent call last):
  File "/usr/lib/python3.8/site-packages/blueman/gui/manager/ManagerDeviceList.py", line 495, in _set_device_cell_data
    surface = self.make_device_icon(row["icon_info"], row["paired"], row["trusted"])
  File "/usr/lib/python3.8/site-packages/blueman/gui/manager/ManagerDeviceList.py", line 184, in make_device_icon
    target = icon_info.load_surface(window)
gi.repository.GLib.Error: g-io-error-quark: Error al abrir el archivo /usr/share/icons/Vimix-Doder-dark/scalable/devices/audio-card.svg: No existe el fichero o el directorio (1)
Traceback (most recent call last):
  File "/usr/lib/python3.8/site-packages/blueman/gui/manager/ManagerDeviceList.py", line 495, in _set_device_cell_data
    surface = self.make_device_icon(row["icon_info"], row["paired"], row["trusted"])
  File "/usr/lib/python3.8/site-packages/blueman/gui/manager/ManagerDeviceList.py", line 184, in make_device_icon
    target = icon_info.load_surface(window)
gi.repository.GLib.Error: g-io-error-quark: Error al abrir el archivo /usr/share/icons/Vimix-Doder-dark/scalable/devices/audio-card.svg: No existe el fichero o el directorio (1)
Traceback (most recent call last):
  File "/usr/lib/python3.8/site-packages/blueman/gui/manager/ManagerDeviceList.py", line 495, in _set_device_cell_data
    surface = self.make_device_icon(row["icon_info"], row["paired"], row["trusted"])
  File "/usr/lib/python3.8/site-packages/blueman/gui/manager/ManagerDeviceList.py", line 184, in make_device_icon
    target = icon_info.load_surface(window)
gi.repository.GLib.Error: g-io-error-quark: Error al abrir el archivo /usr/share/icons/Vimix-Doder-dark/scalable/devices/audio-card.svg: No existe el fichero o el directorio (1)
Traceback (most recent call last):
  File "/usr/lib/python3.8/site-packages/blueman/gui/manager/ManagerDeviceList.py", line 495, in _set_device_cell_data
    surface = self.make_device_icon(row["icon_info"], row["paired"], row["trusted"])
  File "/usr/lib/python3.8/site-packages/blueman/gui/manager/ManagerDeviceList.py", line 184, in make_device_icon
    target = icon_info.load_surface(window)
gi.repository.GLib.Error: g-io-error-quark: Error al abrir el archivo /usr/share/icons/Vimix-Doder-dark/scalable/devices/audio-card.svg: No existe el fichero o el directorio (1)
Traceback (most recent call last):
  File "/usr/lib/python3.8/site-packages/blueman/gui/manager/ManagerDeviceList.py", line 495, in _set_device_cell_data
    surface = self.make_device_icon(row["icon_info"], row["paired"], row["trusted"])
  File "/usr/lib/python3.8/site-packages/blueman/gui/manager/ManagerDeviceList.py", line 184, in make_device_icon
    target = icon_info.load_surface(window)
gi.repository.GLib.Error: g-io-error-quark: Error al abrir el archivo /usr/share/icons/Vimix-Doder-dark/scalable/devices/input-mouse.svg: No existe el fichero o el directorio (1)
Traceback (most recent call last):
  File "/usr/lib/python3.8/site-packages/blueman/gui/manager/ManagerDeviceList.py", line 495, in _set_device_cell_data
    surface = self.make_device_icon(row["icon_info"], row["paired"], row["trusted"])
  File "/usr/lib/python3.8/site-packages/blueman/gui/manager/ManagerDeviceList.py", line 184, in make_device_icon
    target = icon_info.load_surface(window)
gi.repository.GLib.Error: g-io-error-quark: Error al abrir el archivo /usr/share/icons/Vimix-Doder-dark/scalable/devices/input-mouse.svg: No existe el fichero o el directorio (1)
Traceback (most recent call last):
  File "/usr/lib/python3.8/site-packages/blueman/gui/manager/ManagerDeviceList.py", line 495, in _set_device_cell_data
    surface = self.make_device_icon(row["icon_info"], row["paired"], row["trusted"])
  File "/usr/lib/python3.8/site-packages/blueman/gui/manager/ManagerDeviceList.py", line 184, in make_device_icon
    target = icon_info.load_surface(window)
gi.repository.GLib.Error: g-io-error-quark: Error al abrir el archivo /usr/share/icons/Vimix-Doder-dark/scalable/devices/audio-card.svg: No existe el fichero o el directorio (1)
Traceback (most recent call last):
  File "/usr/lib/python3.8/site-packages/blueman/gui/manager/ManagerDeviceList.py", line 495, in _set_device_cell_data
    surface = self.make_device_icon(row["icon_info"], row["paired"], row["trusted"])
  File "/usr/lib/python3.8/site-packages/blueman/gui/manager/ManagerDeviceList.py", line 184, in make_device_icon
    target = icon_info.load_surface(window)
gi.repository.GLib.Error: g-io-error-quark: Error al abrir el archivo /usr/share/icons/Vimix-Doder-dark/scalable/devices/audio-card.svg: No existe el fichero o el directorio (1)
Traceback (most recent call last):
  File "/usr/lib/python3.8/site-packages/blueman/gui/manager/ManagerDeviceList.py", line 495, in _set_device_cell_data
    surface = self.make_device_icon(row["icon_info"], row["paired"], row["trusted"])
  File "/usr/lib/python3.8/site-packages/blueman/gui/manager/ManagerDeviceList.py", line 184, in make_device_icon
    target = icon_info.load_surface(window)
gi.repository.GLib.Error: g-io-error-quark: Error al abrir el archivo /usr/share/icons/Vimix-Doder-dark/scalable/devices/audio-card.svg: No existe el fichero o el directorio (1)
Traceback (most recent call last):
  File "/usr/lib/python3.8/site-packages/blueman/gui/manager/ManagerDeviceList.py", line 495, in _set_device_cell_data
    surface = self.make_device_icon(row["icon_info"], row["paired"], row["trusted"])
  File "/usr/lib/python3.8/site-packages/blueman/gui/manager/ManagerDeviceList.py", line 184, in make_device_icon
    target = icon_info.load_surface(window)
gi.repository.GLib.Error: g-io-error-quark: Error al abrir el archivo /usr/share/icons/Vimix-Doder-dark/scalable/devices/input-mouse.svg: No existe el fichero o el directorio (1)
Traceback (most recent call last):
  File "/usr/lib/python3.8/site-packages/blueman/gui/manager/ManagerDeviceList.py", line 495, in _set_device_cell_data
    surface = self.make_device_icon(row["icon_info"], row["paired"], row["trusted"])
  File "/usr/lib/python3.8/site-packages/blueman/gui/manager/ManagerDeviceList.py", line 184, in make_device_icon
    target = icon_info.load_surface(window)
gi.repository.GLib.Error: g-io-error-quark: Error al abrir el archivo /usr/share/icons/Vimix-Doder-dark/scalable/devices/input-mouse.svg: No existe el fichero o el directorio (1)
Traceback (most recent call last):
  File "/usr/lib/python3.8/site-packages/blueman/gui/manager/ManagerDeviceList.py", line 495, in _set_device_cell_data
    surface = self.make_device_icon(row["icon_info"], row["paired"], row["trusted"])
  File "/usr/lib/python3.8/site-packages/blueman/gui/manager/ManagerDeviceList.py", line 184, in make_device_icon
    target = icon_info.load_surface(window)
gi.repository.GLib.Error: g-io-error-quark: Error al abrir el archivo /usr/share/icons/Vimix-Doder-dark/scalable/devices/audio-card.svg: No existe el fichero o el directorio (1)
Traceback (most recent call last):
  File "/usr/lib/python3.8/site-packages/blueman/gui/manager/ManagerDeviceList.py", line 495, in _set_device_cell_data
    surface = self.make_device_icon(row["icon_info"], row["paired"], row["trusted"])
  File "/usr/lib/python3.8/site-packages/blueman/gui/manager/ManagerDeviceList.py", line 184, in make_device_icon
    target = icon_info.load_surface(window)
gi.repository.GLib.Error: g-io-error-quark: Error al abrir el archivo /usr/share/icons/Vimix-Doder-dark/scalable/devices/audio-card.svg: No existe el fichero o el directorio (1)
Traceback (most recent call last):
  File "/usr/lib/python3.8/site-packages/blueman/gui/manager/ManagerDeviceList.py", line 495, in _set_device_cell_data
    surface = self.make_device_icon(row["icon_info"], row["paired"], row["trusted"])
  File "/usr/lib/python3.8/site-packages/blueman/gui/manager/ManagerDeviceList.py", line 184, in make_device_icon
    target = icon_info.load_surface(window)
gi.repository.GLib.Error: g-io-error-quark: Error al abrir el archivo /usr/share/icons/Vimix-Doder-dark/scalable/devices/input-mouse.svg: No existe el fichero o el directorio (1)
Traceback (most recent call last):
  File "/usr/lib/python3.8/site-packages/blueman/gui/manager/ManagerDeviceList.py", line 495, in _set_device_cell_data
    surface = self.make_device_icon(row["icon_info"], row["paired"], row["trusted"])
  File "/usr/lib/python3.8/site-packages/blueman/gui/manager/ManagerDeviceList.py", line 184, in make_device_icon
    target = icon_info.load_surface(window)
gi.repository.GLib.Error: g-io-error-quark: Error al abrir el archivo /usr/share/icons/Vimix-Doder-dark/scalable/devices/input-mouse.svg: No existe el fichero o el directorio (1)
Traceback (most recent call last):
  File "/usr/lib/python3.8/site-packages/blueman/gui/manager/ManagerDeviceList.py", line 495, in _set_device_cell_data
    surface = self.make_device_icon(row["icon_info"], row["paired"], row["trusted"])
  File "/usr/lib/python3.8/site-packages/blueman/gui/manager/ManagerDeviceList.py", line 184, in make_device_icon
    target = icon_info.load_surface(window)
gi.repository.GLib.Error: g-io-error-quark: Error al abrir el archivo /usr/share/icons/Vimix-Doder-dark/scalable/devices/audio-card.svg: No existe el fichero o el directorio (1)
Traceback (most recent call last):
  File "/usr/lib/python3.8/site-packages/blueman/gui/manager/ManagerDeviceList.py", line 495, in _set_device_cell_data
    surface = self.make_device_icon(row["icon_info"], row["paired"], row["trusted"])
  File "/usr/lib/python3.8/site-packages/blueman/gui/manager/ManagerDeviceList.py", line 184, in make_device_icon
    target = icon_info.load_surface(window)
gi.repository.GLib.Error: g-io-error-quark: Error al abrir el archivo /usr/share/icons/Vimix-Doder-dark/scalable/devices/audio-card.svg: No existe el fichero o el directorio (1)
Traceback (most recent call last):
  File "/usr/lib/python3.8/site-packages/blueman/gui/manager/ManagerDeviceList.py", line 495, in _set_device_cell_data
    surface = self.make_device_icon(row["icon_info"], row["paired"], row["trusted"])
  File "/usr/lib/python3.8/site-packages/blueman/gui/manager/ManagerDeviceList.py", line 184, in make_device_icon
    target = icon_info.load_surface(window)
gi.repository.GLib.Error: g-io-error-quark: Error al abrir el archivo /usr/share/icons/Vimix-Doder-dark/scalable/devices/input-mouse.svg: No existe el fichero o el directorio (1)
Traceback (most recent call last):
  File "/usr/lib/python3.8/site-packages/blueman/gui/manager/ManagerDeviceList.py", line 495, in _set_device_cell_data
    surface = self.make_device_icon(row["icon_info"], row["paired"], row["trusted"])
  File "/usr/lib/python3.8/site-packages/blueman/gui/manager/ManagerDeviceList.py", line 184, in make_device_icon
    target = icon_info.load_surface(window)
gi.repository.GLib.Error: g-io-error-quark: Error al abrir el archivo /usr/share/icons/Vimix-Doder-dark/scalable/devices/input-mouse.svg: No existe el fichero o el directorio (1)
Traceback (most recent call last):
  File "/usr/lib/python3.8/site-packages/blueman/gui/manager/ManagerDeviceList.py", line 495, in _set_device_cell_data
    surface = self.make_device_icon(row["icon_info"], row["paired"], row["trusted"])
  File "/usr/lib/python3.8/site-packages/blueman/gui/manager/ManagerDeviceList.py", line 184, in make_device_icon
    target = icon_info.load_surface(window)
gi.repository.GLib.Error: g-io-error-quark: Error al abrir el archivo /usr/share/icons/Vimix-Doder-dark/scalable/devices/audio-card.svg: No existe el fichero o el directorio (1)
Traceback (most recent call last):
  File "/usr/lib/python3.8/site-packages/blueman/gui/manager/ManagerDeviceList.py", line 495, in _set_device_cell_data
    surface = self.make_device_icon(row["icon_info"], row["paired"], row["trusted"])
  File "/usr/lib/python3.8/site-packages/blueman/gui/manager/ManagerDeviceList.py", line 184, in make_device_icon
    target = icon_info.load_surface(window)
gi.repository.GLib.Error: g-io-error-quark: Error al abrir el archivo /usr/share/icons/Vimix-Doder-dark/scalable/devices/audio-card.svg: No existe el fichero o el directorio (1)
Traceback (most recent call last):
  File "/usr/lib/python3.8/site-packages/blueman/gui/manager/ManagerDeviceList.py", line 495, in _set_device_cell_data
    surface = self.make_device_icon(row["icon_info"], row["paired"], row["trusted"])
  File "/usr/lib/python3.8/site-packages/blueman/gui/manager/ManagerDeviceList.py", line 184, in make_device_icon
    target = icon_info.load_surface(window)
gi.repository.GLib.Error: g-io-error-quark: Error al abrir el archivo /usr/share/icons/Vimix-Doder-dark/scalable/devices/input-mouse.svg: No existe el fichero o el directorio (1)
Traceback (most recent call last):
  File "/usr/lib/python3.8/site-packages/blueman/gui/manager/ManagerDeviceList.py", line 495, in _set_device_cell_data
    surface = self.make_device_icon(row["icon_info"], row["paired"], row["trusted"])
  File "/usr/lib/python3.8/site-packages/blueman/gui/manager/ManagerDeviceList.py", line 184, in make_device_icon
    target = icon_info.load_surface(window)
gi.repository.GLib.Error: g-io-error-quark: Error al abrir el archivo /usr/share/icons/Vimix-Doder-dark/scalable/devices/input-mouse.svg: No existe el fichero o el directorio (1)
Traceback (most recent call last):
  File "/usr/lib/python3.8/site-packages/blueman/gui/manager/ManagerDeviceList.py", line 495, in _set_device_cell_data
    surface = self.make_device_icon(row["icon_info"], row["paired"], row["trusted"])
  File "/usr/lib/python3.8/site-packages/blueman/gui/manager/ManagerDeviceList.py", line 184, in make_device_icon
    target = icon_info.load_surface(window)
gi.repository.GLib.Error: g-io-error-quark: Error al abrir el archivo /usr/share/icons/Vimix-Doder-dark/scalable/devices/audio-card.svg: No existe el fichero o el directorio (1)
Traceback (most recent call last):
  File "/usr/lib/python3.8/site-packages/blueman/gui/manager/ManagerDeviceList.py", line 495, in _set_device_cell_data
    surface = self.make_device_icon(row["icon_info"], row["paired"], row["trusted"])
  File "/usr/lib/python3.8/site-packages/blueman/gui/manager/ManagerDeviceList.py", line 184, in make_device_icon
    target = icon_info.load_surface(window)
gi.repository.GLib.Error: g-io-error-quark: Error al abrir el archivo /usr/share/icons/Vimix-Doder-dark/scalable/devices/audio-card.svg: No existe el fichero o el directorio (1)
Traceback (most recent call last):
  File "/usr/lib/python3.8/site-packages/blueman/gui/manager/ManagerDeviceList.py", line 495, in _set_device_cell_data
    surface = self.make_device_icon(row["icon_info"], row["paired"], row["trusted"])
  File "/usr/lib/python3.8/site-packages/blueman/gui/manager/ManagerDeviceList.py", line 184, in make_device_icon
    target = icon_info.load_surface(window)
gi.repository.GLib.Error: g-io-error-quark: Error al abrir el archivo /usr/share/icons/Vimix-Doder-dark/scalable/devices/input-mouse.svg: No existe el fichero o el directorio (1)
Traceback (most recent call last):
  File "/usr/lib/python3.8/site-packages/blueman/gui/manager/ManagerDeviceList.py", line 495, in _set_device_cell_data
    surface = self.make_device_icon(row["icon_info"], row["paired"], row["trusted"])
  File "/usr/lib/python3.8/site-packages/blueman/gui/manager/ManagerDeviceList.py", line 184, in make_device_icon
    target = icon_info.load_surface(window)
gi.repository.GLib.Error: g-io-error-quark: Error al abrir el archivo /usr/share/icons/Vimix-Doder-dark/scalable/devices/input-mouse.svg: No existe el fichero o el directorio (1)
Traceback (most recent call last):
  File "/usr/lib/python3.8/site-packages/blueman/gui/manager/ManagerDeviceList.py", line 495, in _set_device_cell_data
    surface = self.make_device_icon(row["icon_info"], row["paired"], row["trusted"])
  File "/usr/lib/python3.8/site-packages/blueman/gui/manager/ManagerDeviceList.py", line 184, in make_device_icon
    target = icon_info.load_surface(window)
gi.repository.GLib.Error: g-io-error-quark: Error al abrir el archivo /usr/share/icons/Vimix-Doder-dark/scalable/devices/audio-card.svg: No existe el fichero o el directorio (1)
Traceback (most recent call last):
  File "/usr/lib/python3.8/site-packages/blueman/gui/manager/ManagerDeviceList.py", line 495, in _set_device_cell_data
    surface = self.make_device_icon(row["icon_info"], row["paired"], row["trusted"])
  File "/usr/lib/python3.8/site-packages/blueman/gui/manager/ManagerDeviceList.py", line 184, in make_device_icon
    target = icon_info.load_surface(window)
gi.repository.GLib.Error: g-io-error-quark: Error al abrir el archivo /usr/share/icons/Vimix-Doder-dark/scalable/devices/audio-card.svg: No existe el fichero o el directorio (1)
Traceback (most recent call last):
  File "/usr/lib/python3.8/site-packages/blueman/gui/manager/ManagerDeviceList.py", line 495, in _set_device_cell_data
    surface = self.make_device_icon(row["icon_info"], row["paired"], row["trusted"])
  File "/usr/lib/python3.8/site-packages/blueman/gui/manager/ManagerDeviceList.py", line 184, in make_device_icon
    target = icon_info.load_surface(window)
gi.repository.GLib.Error: g-io-error-quark: Error al abrir el archivo /usr/share/icons/Vimix-Doder-dark/scalable/devices/input-mouse.svg: No existe el fichero o el directorio (1)
Traceback (most recent call last):
  File "/usr/lib/python3.8/site-packages/blueman/gui/manager/ManagerDeviceList.py", line 495, in _set_device_cell_data
    surface = self.make_device_icon(row["icon_info"], row["paired"], row["trusted"])
  File "/usr/lib/python3.8/site-packages/blueman/gui/manager/ManagerDeviceList.py", line 184, in make_device_icon
    target = icon_info.load_surface(window)
gi.repository.GLib.Error: g-io-error-quark: Error al abrir el archivo /usr/share/icons/Vimix-Doder-dark/scalable/devices/input-mouse.svg: No existe el fichero o el directorio (1)
Traceback (most recent call last):
  File "/usr/lib/python3.8/site-packages/blueman/gui/manager/ManagerDeviceList.py", line 495, in _set_device_cell_data
    surface = self.make_device_icon(row["icon_info"], row["paired"], row["trusted"])
  File "/usr/lib/python3.8/site-packages/blueman/gui/manager/ManagerDeviceList.py", line 184, in make_device_icon
    target = icon_info.load_surface(window)
gi.repository.GLib.Error: g-io-error-quark: Error al abrir el archivo /usr/share/icons/Vimix-Doder-dark/scalable/devices/audio-card.svg: No existe el fichero o el directorio (1)
Traceback (most recent call last):
  File "/usr/lib/python3.8/site-packages/blueman/gui/manager/ManagerDeviceList.py", line 495, in _set_device_cell_data
    surface = self.make_device_icon(row["icon_info"], row["paired"], row["trusted"])
  File "/usr/lib/python3.8/site-packages/blueman/gui/manager/ManagerDeviceList.py", line 184, in make_device_icon
    target = icon_info.load_surface(window)
gi.repository.GLib.Error: g-io-error-quark: Error al abrir el archivo /usr/share/icons/Vimix-Doder-dark/scalable/devices/audio-card.svg: No existe el fichero o el directorio (1)
Traceback (most recent call last):
  File "/usr/lib/python3.8/site-packages/blueman/gui/manager/ManagerDeviceList.py", line 495, in _set_device_cell_data
    surface = self.make_device_icon(row["icon_info"], row["paired"], row["trusted"])
  File "/usr/lib/python3.8/site-packages/blueman/gui/manager/ManagerDeviceList.py", line 184, in make_device_icon
    target = icon_info.load_surface(window)
gi.repository.GLib.Error: g-io-error-quark: Error al abrir el archivo /usr/share/icons/Vimix-Doder-dark/scalable/devices/input-mouse.svg: No existe el fichero o el directorio (1)
Traceback (most recent call last):
  File "/usr/lib/python3.8/site-packages/blueman/gui/manager/ManagerDeviceList.py", line 495, in _set_device_cell_data
    surface = self.make_device_icon(row["icon_info"], row["paired"], row["trusted"])
  File "/usr/lib/python3.8/site-packages/blueman/gui/manager/ManagerDeviceList.py", line 184, in make_device_icon
    target = icon_info.load_surface(window)
gi.repository.GLib.Error: g-io-error-quark: Error al abrir el archivo /usr/share/icons/Vimix-Doder-dark/scalable/devices/input-mouse.svg: No existe el fichero o el directorio (1)
Traceback (most recent call last):
  File "/usr/lib/python3.8/site-packages/blueman/gui/manager/ManagerDeviceList.py", line 495, in _set_device_cell_data
    surface = self.make_device_icon(row["icon_info"], row["paired"], row["trusted"])
  File "/usr/lib/python3.8/site-packages/blueman/gui/manager/ManagerDeviceList.py", line 184, in make_device_icon
    target = icon_info.load_surface(window)
gi.repository.GLib.Error: g-io-error-quark: Error al abrir el archivo /usr/share/icons/Vimix-Doder-dark/scalable/devices/audio-card.svg: No existe el fichero o el directorio (1)
Traceback (most recent call last):
  File "/usr/lib/python3.8/site-packages/blueman/gui/manager/ManagerDeviceList.py", line 495, in _set_device_cell_data
    surface = self.make_device_icon(row["icon_info"], row["paired"], row["trusted"])
  File "/usr/lib/python3.8/site-packages/blueman/gui/manager/ManagerDeviceList.py", line 184, in make_device_icon
    target = icon_info.load_surface(window)
gi.repository.GLib.Error: g-io-error-quark: Error al abrir el archivo /usr/share/icons/Vimix-Doder-dark/scalable/devices/audio-card.svg: No existe el fichero o el directorio (1)
Traceback (most recent call last):
  File "/usr/lib/python3.8/site-packages/blueman/gui/manager/ManagerDeviceList.py", line 495, in _set_device_cell_data
    surface = self.make_device_icon(row["icon_info"], row["paired"], row["trusted"])
  File "/usr/lib/python3.8/site-packages/blueman/gui/manager/ManagerDeviceList.py", line 184, in make_device_icon
    target = icon_info.load_surface(window)
gi.repository.GLib.Error: g-io-error-quark: Error al abrir el archivo /usr/share/icons/Vimix-Doder-dark/scalable/devices/input-mouse.svg: No existe el fichero o el directorio (1)
Traceback (most recent call last):
  File "/usr/lib/python3.8/site-packages/blueman/gui/manager/ManagerDeviceList.py", line 495, in _set_device_cell_data
    surface = self.make_device_icon(row["icon_info"], row["paired"], row["trusted"])
  File "/usr/lib/python3.8/site-packages/blueman/gui/manager/ManagerDeviceList.py", line 184, in make_device_icon
    target = icon_info.load_surface(window)
gi.repository.GLib.Error: g-io-error-quark: Error al abrir el archivo /usr/share/icons/Vimix-Doder-dark/scalable/devices/input-mouse.svg: No existe el fichero o el directorio (1)
Traceback (most recent call last):
  File "/usr/lib/python3.8/site-packages/blueman/gui/manager/ManagerDeviceList.py", line 495, in _set_device_cell_data
    surface = self.make_device_icon(row["icon_info"], row["paired"], row["trusted"])
  File "/usr/lib/python3.8/site-packages/blueman/gui/manager/ManagerDeviceList.py", line 184, in make_device_icon
    target = icon_info.load_surface(window)
gi.repository.GLib.Error: g-io-error-quark: Error al abrir el archivo /usr/share/icons/Vimix-Doder-dark/scalable/devices/audio-card.svg: No existe el fichero o el directorio (1)
Traceback (most recent call last):
  File "/usr/lib/python3.8/site-packages/blueman/gui/manager/ManagerDeviceList.py", line 495, in _set_device_cell_data
    surface = self.make_device_icon(row["icon_info"], row["paired"], row["trusted"])
  File "/usr/lib/python3.8/site-packages/blueman/gui/manager/ManagerDeviceList.py", line 184, in make_device_icon
    target = icon_info.load_surface(window)
gi.repository.GLib.Error: g-io-error-quark: Error al abrir el archivo /usr/share/icons/Vimix-Doder-dark/scalable/devices/audio-card.svg: No existe el fichero o el directorio (1)
Traceback (most recent call last):
  File "/usr/lib/python3.8/site-packages/blueman/gui/manager/ManagerDeviceList.py", line 495, in _set_device_cell_data
    surface = self.make_device_icon(row["icon_info"], row["paired"], row["trusted"])
  File "/usr/lib/python3.8/site-packages/blueman/gui/manager/ManagerDeviceList.py", line 184, in make_device_icon
    target = icon_info.load_surface(window)
gi.repository.GLib.Error: g-io-error-quark: Error al abrir el archivo /usr/share/icons/Vimix-Doder-dark/scalable/devices/input-mouse.svg: No existe el fichero o el directorio (1)
Traceback (most recent call last):
  File "/usr/lib/python3.8/site-packages/blueman/gui/manager/ManagerDeviceList.py", line 495, in _set_device_cell_data
    surface = self.make_device_icon(row["icon_info"], row["paired"], row["trusted"])
  File "/usr/lib/python3.8/site-packages/blueman/gui/manager/ManagerDeviceList.py", line 184, in make_device_icon
    target = icon_info.load_surface(window)
gi.repository.GLib.Error: g-io-error-quark: Error al abrir el archivo /usr/share/icons/Vimix-Doder-dark/scalable/devices/input-mouse.svg: No existe el fichero o el directorio (1)
Traceback (most recent call last):
  File "/usr/lib/python3.8/site-packages/blueman/gui/manager/ManagerDeviceList.py", line 495, in _set_device_cell_data
    surface = self.make_device_icon(row["icon_info"], row["paired"], row["trusted"])
  File "/usr/lib/python3.8/site-packages/blueman/gui/manager/ManagerDeviceList.py", line 184, in make_device_icon
    target = icon_info.load_surface(window)
gi.repository.GLib.Error: g-io-error-quark: Error al abrir el archivo /usr/share/icons/Vimix-Doder-dark/scalable/devices/audio-card.svg: No existe el fichero o el directorio (1)
Traceback (most recent call last):
  File "/usr/lib/python3.8/site-packages/blueman/gui/manager/ManagerDeviceList.py", line 495, in _set_device_cell_data
    surface = self.make_device_icon(row["icon_info"], row["paired"], row["trusted"])
  File "/usr/lib/python3.8/site-packages/blueman/gui/manager/ManagerDeviceList.py", line 184, in make_device_icon
    target = icon_info.load_surface(window)
gi.repository.GLib.Error: g-io-error-quark: Error al abrir el archivo /usr/share/icons/Vimix-Doder-dark/scalable/devices/audio-card.svg: No existe el fichero o el directorio (1)
Traceback (most recent call last):
  File "/usr/lib/python3.8/site-packages/blueman/gui/manager/ManagerDeviceList.py", line 495, in _set_device_cell_data
    surface = self.make_device_icon(row["icon_info"], row["paired"], row["trusted"])
  File "/usr/lib/python3.8/site-packages/blueman/gui/manager/ManagerDeviceList.py", line 184, in make_device_icon
    target = icon_info.load_surface(window)
gi.repository.GLib.Error: g-io-error-quark: Error al abrir el archivo /usr/share/icons/Vimix-Doder-dark/scalable/devices/input-mouse.svg: No existe el fichero o el directorio (1)
Traceback (most recent call last):
  File "/usr/lib/python3.8/site-packages/blueman/gui/manager/ManagerDeviceList.py", line 495, in _set_device_cell_data
    surface = self.make_device_icon(row["icon_info"], row["paired"], row["trusted"])
  File "/usr/lib/python3.8/site-packages/blueman/gui/manager/ManagerDeviceList.py", line 184, in make_device_icon
    target = icon_info.load_surface(window)
gi.repository.GLib.Error: g-io-error-quark: Error al abrir el archivo /usr/share/icons/Vimix-Doder-dark/scalable/devices/input-mouse.svg: No existe el fichero o el directorio (1)
Traceback (most recent call last):
  File "/usr/lib/python3.8/site-packages/blueman/gui/manager/ManagerDeviceList.py", line 495, in _set_device_cell_data
    surface = self.make_device_icon(row["icon_info"], row["paired"], row["trusted"])
  File "/usr/lib/python3.8/site-packages/blueman/gui/manager/ManagerDeviceList.py", line 184, in make_device_icon
    target = icon_info.load_surface(window)
gi.repository.GLib.Error: g-io-error-quark: Error al abrir el archivo /usr/share/icons/Vimix-Doder-dark/scalable/devices/audio-card.svg: No existe el fichero o el directorio (1)
Traceback (most recent call last):
  File "/usr/lib/python3.8/site-packages/blueman/gui/manager/ManagerDeviceList.py", line 495, in _set_device_cell_data
    surface = self.make_device_icon(row["icon_info"], row["paired"], row["trusted"])
  File "/usr/lib/python3.8/site-packages/blueman/gui/manager/ManagerDeviceList.py", line 184, in make_device_icon
    target = icon_info.load_surface(window)
gi.repository.GLib.Error: g-io-error-quark: Error al abrir el archivo /usr/share/icons/Vimix-Doder-dark/scalable/devices/audio-card.svg: No existe el fichero o el directorio (1)
Traceback (most recent call last):
  File "/usr/lib/python3.8/site-packages/blueman/gui/manager/ManagerDeviceList.py", line 495, in _set_device_cell_data
    surface = self.make_device_icon(row["icon_info"], row["paired"], row["trusted"])
  File "/usr/lib/python3.8/site-packages/blueman/gui/manager/ManagerDeviceList.py", line 184, in make_device_icon
    target = icon_info.load_surface(window)
gi.repository.GLib.Error: g-io-error-quark: Error al abrir el archivo /usr/share/icons/Vimix-Doder-dark/scalable/devices/input-mouse.svg: No existe el fichero o el directorio (1)
Traceback (most recent call last):
  File "/usr/lib/python3.8/site-packages/blueman/gui/manager/ManagerDeviceList.py", line 495, in _set_device_cell_data
    surface = self.make_device_icon(row["icon_info"], row["paired"], row["trusted"])
  File "/usr/lib/python3.8/site-packages/blueman/gui/manager/ManagerDeviceList.py", line 184, in make_device_icon
    target = icon_info.load_surface(window)
gi.repository.GLib.Error: g-io-error-quark: Error al abrir el archivo /usr/share/icons/Vimix-Doder-dark/scalable/devices/input-mouse.svg: No existe el fichero o el directorio (1)
Traceback (most recent call last):
  File "/usr/lib/python3.8/site-packages/blueman/gui/manager/ManagerDeviceList.py", line 495, in _set_device_cell_data
    surface = self.make_device_icon(row["icon_info"], row["paired"], row["trusted"])
  File "/usr/lib/python3.8/site-packages/blueman/gui/manager/ManagerDeviceList.py", line 184, in make_device_icon
    target = icon_info.load_surface(window)
gi.repository.GLib.Error: g-io-error-quark: Error al abrir el archivo /usr/share/icons/Vimix-Doder-dark/scalable/devices/audio-card.svg: No existe el fichero o el directorio (1)
Traceback (most recent call last):
  File "/usr/lib/python3.8/site-packages/blueman/gui/manager/ManagerDeviceList.py", line 495, in _set_device_cell_data
    surface = self.make_device_icon(row["icon_info"], row["paired"], row["trusted"])
  File "/usr/lib/python3.8/site-packages/blueman/gui/manager/ManagerDeviceList.py", line 184, in make_device_icon
    target = icon_info.load_surface(window)
gi.repository.GLib.Error: g-io-error-quark: Error al abrir el archivo /usr/share/icons/Vimix-Doder-dark/scalable/devices/audio-card.svg: No existe el fichero o el directorio (1)
Traceback (most recent call last):
  File "/usr/lib/python3.8/site-packages/blueman/gui/manager/ManagerDeviceList.py", line 495, in _set_device_cell_data
    surface = self.make_device_icon(row["icon_info"], row["paired"], row["trusted"])
  File "/usr/lib/python3.8/site-packages/blueman/gui/manager/ManagerDeviceList.py", line 184, in make_device_icon
    target = icon_info.load_surface(window)
gi.repository.GLib.Error: g-io-error-quark: Error al abrir el archivo /usr/share/icons/Vimix-Doder-dark/scalable/devices/audio-card.svg: No existe el fichero o el directorio (1)
Traceback (most recent call last):
  File "/usr/lib/python3.8/site-packages/blueman/gui/manager/ManagerDeviceList.py", line 495, in _set_device_cell_data
    surface = self.make_device_icon(row["icon_info"], row["paired"], row["trusted"])
  File "/usr/lib/python3.8/site-packages/blueman/gui/manager/ManagerDeviceList.py", line 184, in make_device_icon
    target = icon_info.load_surface(window)
gi.repository.GLib.Error: g-io-error-quark: Error al abrir el archivo /usr/share/icons/Vimix-Doder-dark/scalable/devices/input-mouse.svg: No existe el fichero o el directorio (1)
Traceback (most recent call last):
  File "/usr/lib/python3.8/site-packages/blueman/gui/manager/ManagerDeviceList.py", line 495, in _set_device_cell_data
    surface = self.make_device_icon(row["icon_info"], row["paired"], row["trusted"])
  File "/usr/lib/python3.8/site-packages/blueman/gui/manager/ManagerDeviceList.py", line 184, in make_device_icon
    target = icon_info.load_surface(window)
gi.repository.GLib.Error: g-io-error-quark: Error al abrir el archivo /usr/share/icons/Vimix-Doder-dark/scalable/devices/input-mouse.svg: No existe el fichero o el directorio (1)
Traceback (most recent call last):
  File "/usr/lib/python3.8/site-packages/blueman/gui/manager/ManagerDeviceList.py", line 495, in _set_device_cell_data
    surface = self.make_device_icon(row["icon_info"], row["paired"], row["trusted"])
  File "/usr/lib/python3.8/site-packages/blueman/gui/manager/ManagerDeviceList.py", line 184, in make_device_icon
    target = icon_info.load_surface(window)
gi.repository.GLib.Error: g-io-error-quark: Error al abrir el archivo /usr/share/icons/Vimix-Doder-dark/scalable/devices/audio-card.svg: No existe el fichero o el directorio (1)
Traceback (most recent call last):
  File "/usr/lib/python3.8/site-packages/blueman/gui/manager/ManagerDeviceList.py", line 495, in _set_device_cell_data
    surface = self.make_device_icon(row["icon_info"], row["paired"], row["trusted"])
  File "/usr/lib/python3.8/site-packages/blueman/gui/manager/ManagerDeviceList.py", line 184, in make_device_icon
    target = icon_info.load_surface(window)
gi.repository.GLib.Error: g-io-error-quark: Error al abrir el archivo /usr/share/icons/Vimix-Doder-dark/scalable/devices/audio-card.svg: No existe el fichero o el directorio (1)
Traceback (most recent call last):
  File "/usr/lib/python3.8/site-packages/blueman/gui/manager/ManagerDeviceList.py", line 495, in _set_device_cell_data
    surface = self.make_device_icon(row["icon_info"], row["paired"], row["trusted"])
  File "/usr/lib/python3.8/site-packages/blueman/gui/manager/ManagerDeviceList.py", line 184, in make_device_icon
    target = icon_info.load_surface(window)
gi.repository.GLib.Error: g-io-error-quark: Error al abrir el archivo /usr/share/icons/Vimix-Doder-dark/scalable/devices/input-mouse.svg: No existe el fichero o el directorio (1)
Traceback (most recent call last):
  File "/usr/lib/python3.8/site-packages/blueman/gui/manager/ManagerDeviceList.py", line 495, in _set_device_cell_data
    surface = self.make_device_icon(row["icon_info"], row["paired"], row["trusted"])
  File "/usr/lib/python3.8/site-packages/blueman/gui/manager/ManagerDeviceList.py", line 184, in make_device_icon
    target = icon_info.load_surface(window)
gi.repository.GLib.Error: g-io-error-quark: Error al abrir el archivo /usr/share/icons/Vimix-Doder-dark/scalable/devices/input-mouse.svg: No existe el fichero o el directorio (1)
Traceback (most recent call last):
  File "/usr/lib/python3.8/site-packages/blueman/gui/manager/ManagerDeviceList.py", line 495, in _set_device_cell_data
    surface = self.make_device_icon(row["icon_info"], row["paired"], row["trusted"])
  File "/usr/lib/python3.8/site-packages/blueman/gui/manager/ManagerDeviceList.py", line 184, in make_device_icon
    target = icon_info.load_surface(window)
gi.repository.GLib.Error: g-io-error-quark: Error al abrir el archivo /usr/share/icons/Vimix-Doder-dark/scalable/devices/audio-card.svg: No existe el fichero o el directorio (1)
Traceback (most recent call last):
  File "/usr/lib/python3.8/site-packages/blueman/gui/manager/ManagerDeviceList.py", line 495, in _set_device_cell_data
    surface = self.make_device_icon(row["icon_info"], row["paired"], row["trusted"])
  File "/usr/lib/python3.8/site-packages/blueman/gui/manager/ManagerDeviceList.py", line 184, in make_device_icon
    target = icon_info.load_surface(window)
gi.repository.GLib.Error: g-io-error-quark: Error al abrir el archivo /usr/share/icons/Vimix-Doder-dark/scalable/devices/input-mouse.svg: No existe el fichero o el directorio (1)
Traceback (most recent call last):
  File "/usr/lib/python3.8/site-packages/blueman/gui/manager/ManagerDeviceList.py", line 495, in _set_device_cell_data
    surface = self.make_device_icon(row["icon_info"], row["paired"], row["trusted"])
  File "/usr/lib/python3.8/site-packages/blueman/gui/manager/ManagerDeviceList.py", line 184, in make_device_icon
    target = icon_info.load_surface(window)
gi.repository.GLib.Error: g-io-error-quark: Error al abrir el archivo /usr/share/icons/Vimix-Doder-dark/scalable/devices/input-mouse.svg: No existe el fichero o el directorio (1)
Traceback (most recent call last):
  File "/usr/lib/python3.8/site-packages/blueman/gui/manager/ManagerDeviceList.py", line 495, in _set_device_cell_data
    surface = self.make_device_icon(row["icon_info"], row["paired"], row["trusted"])
  File "/usr/lib/python3.8/site-packages/blueman/gui/manager/ManagerDeviceList.py", line 184, in make_device_icon
    target = icon_info.load_surface(window)
gi.repository.GLib.Error: g-io-error-quark: Error al abrir el archivo /usr/share/icons/Vimix-Doder-dark/scalable/devices/audio-card.svg: No existe el fichero o el directorio (1)
Traceback (most recent call last):
  File "/usr/lib/python3.8/site-packages/blueman/gui/manager/ManagerDeviceList.py", line 495, in _set_device_cell_data
    surface = self.make_device_icon(row["icon_info"], row["paired"], row["trusted"])
  File "/usr/lib/python3.8/site-packages/blueman/gui/manager/ManagerDeviceList.py", line 184, in make_device_icon
    target = icon_info.load_surface(window)
gi.repository.GLib.Error: g-io-error-quark: Error al abrir el archivo /usr/share/icons/Vimix-Doder-dark/scalable/devices/input-mouse.svg: No existe el fichero o el directorio (1)
Traceback (most recent call last):
  File "/usr/lib/python3.8/site-packages/blueman/gui/manager/ManagerDeviceList.py", line 495, in _set_device_cell_data
    surface = self.make_device_icon(row["icon_info"], row["paired"], row["trusted"])
  File "/usr/lib/python3.8/site-packages/blueman/gui/manager/ManagerDeviceList.py", line 184, in make_device_icon
    target = icon_info.load_surface(window)
gi.repository.GLib.Error: g-io-error-quark: Error al abrir el archivo /usr/share/icons/Vimix-Doder-dark/scalable/devices/input-mouse.svg: No existe el fichero o el directorio (1)
blueman-manager version 2.1.3 starting
